<?xml version="1.0" ?>
<robot name="FullBody_Simplified">

<material name="silver">
  <color rgba="0.700 0.700 0.700 1.000"/>
</material>

<link name="L_Pelvisv15_1">
  <inertial>
    <origin xyz="0.07850633428100368 0.0021369098937358915 0.9996061841766282" rpy="0 0 0"/>
    <mass value="12.901786749235924"/>
    <inertia ixx="1300368041.252293" iyy="1302830343.998931" izz="22180147.650835" ixy="-228031.637686" iyz="-2760370.548183" ixz="-101798401.486088"/>
  </inertial>
  <visual>
    <origin xyz="0.0 0.0 0.0" rpy="0 0 0"/>
    <geometry>
      <mesh filename="package://meshes/L_Pelvisv15_1.stl" scale="1.0 1.0 1.0"/>
    </geometry>
    <material name="silver"/>
  </visual>
  <collision>
    <origin xyz="0.0 0.0 0.0" rpy="0 0 0"/>
    <geometry>
      <mesh filename="package://meshes/L_Pelvisv15_1.stl" scale="1.0 1.0 1.0"/>
    </geometry>
  </collision>
</link>

<link name="U_Waist_2v8_1">
  <inertial>
    <origin xyz="-0.03373461624810954 -0.0007679069985090584 0.04639529711879106" rpy="0 0 0"/>
    <mass value="6.477105878848885"/>
    <inertia ixx="812976914.487067" iyy="812589548.591373" izz="11791403.924657" ixy="-59790.357722" iyz="-1075056.476698" ixz="-55099102.831369"/>
  </inertial>
  <visual>
    <origin xyz="-0.11000000000059089 -0.002300500000009677 -1.0694000000000008" rpy="0 0 0"/>
    <geometry>
      <mesh filename="package://meshes/U_Waist_2v8_1.stl" scale="1.0 1.0 1.0"/>
    </geometry>
    <material name="silver"/>
  </visual>
  <collision>
    <origin xyz="-0.11000000000059089 -0.002300500000009677 -1.0694000000000008" rpy="0 0 0"/>
    <geometry>
      <mesh filename="package://meshes/U_Waist_2v8_1.stl" scale="1.0 1.0 1.0"/>
    </geometry>
  </collision>
</link>

<link name="U_Waist_1v3_1">
  <inertial>
    <origin xyz="-0.00026594095858323286 -0.044828908852069825 4.125846770506314e-06" rpy="0 0 0"/>
    <mass value="3.8814634771227143"/>
    <inertia ixx="517906087.83336" iyy="522623762.678878" izz="5486305.862526" ixy="-489574.091897" iyz="-5139723.276555" ixz="-49164438.433366"/>
  </inertial>
  <visual>
    <origin xyz="-0.11000000000058999 -0.056300500000011945 -1.1543999999999996" rpy="0 0 0"/>
    <geometry>
      <mesh filename="package://meshes/U_Waist_1v3_1.stl" scale="1.0 1.0 1.0"/>
    </geometry>
    <material name="silver"/>
  </visual>
  <collision>
    <origin xyz="-0.11000000000058999 -0.056300500000011945 -1.1543999999999996" rpy="0 0 0"/>
    <geometry>
      <mesh filename="package://meshes/U_Waist_1v3_1.stl" scale="1.0 1.0 1.0"/>
    </geometry>
  </collision>
</link>

<link name="U_Body_1v21_1">
  <inertial>
    <origin xyz="0.015155259714987466 0.0017622208909081334 0.15771110211226413" rpy="0 0 0"/>
    <mass value="20.03358554636745"/>
    <inertia ixx="3479638167.234158" iyy="3485071645.950628" izz="28412634.092617" ixy="-442922.927618" iyz="-10628590.14032" ixz="-159704052.761684"/>
  </inertial>
  <visual>
    <origin xyz="-0.04400000000059011 -0.0023005000000118066 -1.1544" rpy="0 0 0"/>
    <geometry>
      <mesh filename="package://meshes/U_Body_1v21_1.stl" scale="1.0 1.0 1.0"/>
    </geometry>
    <material name="silver"/>
  </visual>
  <collision>
    <origin xyz="-0.04400000000059011 -0.0023005000000118066 -1.1544" rpy="0 0 0"/>
    <geometry>
      <mesh filename="package://meshes/U_Body_1v21_1.stl" scale="1.0 1.0 1.0"/>
    </geometry>
  </collision>
</link>

<link name="UL_Shoulder_1v3_1">
  <inertial>
    <origin xyz="-4.8748773014839485e-05 0.004689896578064499 0.05997604799189617" rpy="0 0 0"/>
    <mass value="1.6149801443567293"/>
    <inertia ixx="340103222.697093" iyy="338779286.336507" izz="7210903.402013" ixy="-3456254.346142" iyz="-37492693.420307" ixz="-30955605.478422"/>
  </inertial>
  <visual>
    <origin xyz="-0.1330000000009437 -0.15630050000001602 -1.3818999999999977" rpy="0 0 0"/>
    <geometry>
      <mesh filename="package://meshes/UL_Shoulder_1v3_1.stl" scale="1.0 1.0 1.0"/>
    </geometry>
    <material name="silver"/>
  </visual>
  <collision>
    <origin xyz="-0.1330000000009437 -0.15630050000001602 -1.3818999999999977" rpy="0 0 0"/>
    <geometry>
      <mesh filename="package://meshes/UL_Shoulder_1v3_1.stl" scale="1.0 1.0 1.0"/>
    </geometry>
  </collision>
</link>

<link name="UR_Shoulder_1v3_1">
  <inertial>
    <origin xyz="4.874877301423552e-05 -0.0046898965780623495 0.05997604799189446" rpy="0 0 0"/>
    <mass value="1.6149801443567293"/>
    <inertia ixx="339867416.474351" iyy="338783474.263261" izz="6979285.106019" ixy="3360103.180516" iyz="36421411.152582" ixz="-30978992.047128"/>
  </inertial>
  <visual>
    <origin xyz="-0.1330000000009499 0.15169949999998478 -1.381900000000005" rpy="0 0 0"/>
    <geometry>
      <mesh filename="package://meshes/UR_Shoulder_1v3_1.stl" scale="1.0 1.0 1.0"/>
    </geometry>
    <material name="silver"/>
  </visual>
  <collision>
    <origin xyz="-0.1330000000009499 0.15169949999998478 -1.381900000000005" rpy="0 0 0"/>
    <geometry>
      <mesh filename="package://meshes/UR_Shoulder_1v3_1.stl" scale="1.0 1.0 1.0"/>
    </geometry>
  </collision>
</link>

<link name="UR_Shoulder_2v2_1">
  <inertial>
    <origin xyz="-0.0011896266413214996 -0.05641758337486831 2.0703386736897757e-05" rpy="0 0 0"/>
    <mass value="0.23812084762668878"/>
    <inertia ixx="101302318.682045" iyy="99308062.843852" izz="3720781.804511" ixy="1497006.23194" iyz="16474719.178202" ixz="-8965228.241344"/>
  </inertial>
  <visual>
    <origin xyz="-0.13300000000094991 0.18579949999998424 -1.4469000000000047" rpy="0 0 0"/>
    <geometry>
      <mesh filename="package://meshes/UR_Shoulder_2v2_1.stl" scale="1.0 1.0 1.0"/>
    </geometry>
    <material name="silver"/>
  </visual>
  <collision>
    <origin xyz="-0.13300000000094991 0.18579949999998424 -1.4469000000000047" rpy="0 0 0"/>
    <geometry>
      <mesh filename="package://meshes/UR_Shoulder_2v2_1.stl" scale="1.0 1.0 1.0"/>
    </geometry>
  </collision>
</link>

<link name="UR_Shoulder_3v2_1">
  <inertial>
    <origin xyz="-0.03031024672003575 0.00024001246642271212 -0.04860440459138914" rpy="0 0 0"/>
    <mass value="2.834944399295703"/>
    <inertia ixx="580705168.807843" iyy="560289483.327534" izz="31092525.382827" ixy="11552418.288368" iyz="119129997.175555" ixz="-53777605.308678"/>
  </inertial>
  <visual>
    <origin xyz="-0.16590000000095226 0.300799499999984 -1.4469000000000065" rpy="0 0 0"/>
    <geometry>
      <mesh filename="package://meshes/UR_Shoulder_3v2_1.stl" scale="1.0 1.0 1.0"/>
    </geometry>
    <material name="silver"/>
  </visual>
  <collision>
    <origin xyz="-0.16590000000095226 0.300799499999984 -1.4469000000000065" rpy="0 0 0"/>
    <geometry>
      <mesh filename="package://meshes/UR_Shoulder_3v2_1.stl" scale="1.0 1.0 1.0"/>
    </geometry>
  </collision>
</link>

<link name="UR_Arm_1v2_1">
  <inertial>
    <origin xyz="-0.019862841377670755 0.01187282890310268 -0.11196452842298726" rpy="0 0 0"/>
    <mass value="0.5789025929463171"/>
    <inertia ixx="90726658.748431" iyy="86611231.616323" izz="5742388.927361" ixy="1922652.358867" iyz="20510975.344388" ixz="-8047901.835131"/>
  </inertial>
  <visual>
    <origin xyz="-0.13300000000095155 0.30079949999998706 -1.3188000000000042" rpy="0 0 0"/>
    <geometry>
      <mesh filename="package://meshes/UR_Arm_1v2_1.stl" scale="1.0 1.0 1.0"/>
    </geometry>
    <material name="silver"/>
  </visual>
  <collision>
    <origin xyz="-0.13300000000095155 0.30079949999998706 -1.3188000000000042" rpy="0 0 0"/>
    <geometry>
      <mesh filename="package://meshes/UR_Arm_1v2_1.stl" scale="1.0 1.0 1.0"/>
    </geometry>
  </collision>
</link>

<link name="UR_Arm_2v6_1">
  <inertial>
    <origin xyz="-0.03049076949479984 -0.017673491273958817 -0.05169610810874318" rpy="0 0 0"/>
    <mass value="1.925249848858931"/>
    <inertia ixx="232698695.895426" iyy="220346932.238992" izz="19366552.669425" ixy="7347678.922484" iyz="58213738.183335" ixz="-27252033.531503"/>
  </inertial>
  <visual>
    <origin xyz="-0.16400000000095147 0.2682994999999901 -1.1118000000000041" rpy="0 0 0"/>
    <geometry>
      <mesh filename="package://meshes/UR_Arm_2v6_1.stl" scale="1.0 1.0 1.0"/>
    </geometry>
    <material name="silver"/>
  </visual>
  <collision>
    <origin xyz="-0.16400000000095147 0.2682994999999901 -1.1118000000000041" rpy="0 0 0"/>
    <geometry>
      <mesh filename="package://meshes/UR_Arm_2v6_1.stl" scale="1.0 1.0 1.0"/>
    </geometry>
  </collision>
</link>

<link name="UR_Arm_3v3_1">
  <inertial>
    <origin xyz="-0.016384028005943723 0.00010144118513700563 -0.07699779641120244" rpy="0 0 0"/>
    <mass value="0.40861586219416696"/>
    <inertia ixx="37815548.38814" iyy="34688958.066492" izz="4320829.288508" ixy="1435744.912187" iyz="11221835.501331" ixz="-4372443.841567"/>
  </inertial>
  <visual>
    <origin xyz="-0.1330000000009525 0.3007994999999938 -0.9868000000000052" rpy="0 0 0"/>
    <geometry>
      <mesh filename="package://meshes/UR_Arm_3v3_1.stl" scale="1.0 1.0 1.0"/>
    </geometry>
    <material name="silver"/>
  </visual>
  <collision>
    <origin xyz="-0.1330000000009525 0.3007994999999938 -0.9868000000000052" rpy="0 0 0"/>
    <geometry>
      <mesh filename="package://meshes/UR_Arm_3v3_1.stl" scale="1.0 1.0 1.0"/>
    </geometry>
  </collision>
</link>

<link name="UL_Shoulder_2v3_1">
  <inertial>
    <origin xyz="-0.00118962664132372 0.056417583375104774 2.0703386734055585e-05" rpy="0 0 0"/>
    <mass value="0.4701009156097212"/>
    <inertia ixx="101403090.411026" iyy="99303165.852656" izz="3826369.916372" ixy="-1525439.035264" iyz="-16786834.307968" ixz="-8964785.81091"/>
  </inertial>
  <visual>
    <origin xyz="-0.13300000000094273 -0.19040050000001624 -1.446899999999997" rpy="0 0 0"/>
    <geometry>
      <mesh filename="package://meshes/UL_Shoulder_2v3_1.stl" scale="1.0 1.0 1.0"/>
    </geometry>
    <material name="silver"/>
  </visual>
  <collision>
    <origin xyz="-0.13300000000094273 -0.19040050000001624 -1.446899999999997" rpy="0 0 0"/>
    <geometry>
      <mesh filename="package://meshes/UL_Shoulder_2v3_1.stl" scale="1.0 1.0 1.0"/>
    </geometry>
  </collision>
</link>

<link name="UL_Shoulder_3v3_1">
  <inertial>
    <origin xyz="-0.034710246720033366 0.0002400124664215042 -0.048604404591388574" rpy="0 0 0"/>
    <mass value="2.834944399295703"/>
    <inertia ixx="581578277.621158" iyy="560289483.327524" izz="31965634.196151" ixy="-11746937.678188" iyz="-121149124.480451" ixz="-53777605.308674"/>
  </inertial>
  <visual>
    <origin xyz="-0.1703000000009401 -0.30540050000001745 -1.446899999999995" rpy="0 0 0"/>
    <geometry>
      <mesh filename="package://meshes/UL_Shoulder_3v3_1.stl" scale="1.0 1.0 1.0"/>
    </geometry>
    <material name="silver"/>
  </visual>
  <collision>
    <origin xyz="-0.1703000000009401 -0.30540050000001745 -1.446899999999995" rpy="0 0 0"/>
    <geometry>
      <mesh filename="package://meshes/UL_Shoulder_3v3_1.stl" scale="1.0 1.0 1.0"/>
    </geometry>
  </collision>
</link>

<link name="UR_Wrist_1v6_1">
  <inertial>
    <origin xyz="-0.03825850349237335 0.004774228530308378 -0.023263815479626828" rpy="0 0 0"/>
    <mass value="0.7829866998307424"/>
    <inertia ixx="59542866.784772" iyy="54043515.556638" izz="8260495.470501" ixy="3051481.330894" iyz="18998986.184632" ixz="-8452582.401832"/>
  </inertial>
  <visual>
    <origin xyz="-0.16999999947643227 0.3006725000495791 -0.8430001122209225" rpy="0 0 0"/>
    <geometry>
      <mesh filename="package://meshes/UR_Wrist_1v6_1.stl" scale="1.0 1.0 1.0"/>
    </geometry>
    <material name="silver"/>
  </visual>
  <collision>
    <origin xyz="-0.16999999947643227 0.3006725000495791 -0.8430001122209225" rpy="0 0 0"/>
    <geometry>
      <mesh filename="package://meshes/UR_Wrist_1v6_1.stl" scale="1.0 1.0 1.0"/>
    </geometry>
  </collision>
</link>

<link name="UR_Wrist_2v3_1">
  <inertial>
    <origin xyz="-8.812031992988523e-11 0.03160245308317016 -0.021170872195009877" rpy="0 0 0"/>
    <mass value="0.12362354927744214"/>
    <inertia ixx="8521140.854616" iyy="7628273.118828" izz="1337975.573307" ixy="491610.014628" iyz="2859640.282943" ixz="-1272153.989692"/>
  </inertial>
  <visual>
    <origin xyz="-0.13299999947643085 0.33063007413210294 -0.7949736220817306" rpy="0 0 0"/>
    <geometry>
      <mesh filename="package://meshes/UR_Wrist_2v3_1.stl" scale="1.0 1.0 1.0"/>
    </geometry>
    <material name="silver"/>
  </visual>
  <collision>
    <origin xyz="-0.13299999947643085 0.33063007413210294 -0.7949736220817306" rpy="0 0 0"/>
    <geometry>
      <mesh filename="package://meshes/UR_Wrist_2v3_1.stl" scale="1.0 1.0 1.0"/>
    </geometry>
  </collision>
</link>

<link name="UR_Hand_1v3_1">
  <inertial>
    <origin xyz="0.02002554203355409 0.04078008753078379 -0.06483603718028277" rpy="0 0 0"/>
    <mass value="0.3159262316423516"/>
    <inertia ixx="17687954.577664" iyy="15802312.231279" izz="3055356.650977" ixy="1182883.37237" iyz="6081967.321708" ixz="-2962579.283163"/>
  </inertial>
  <visual>
    <origin xyz="-0.11532232994676837 0.3182746084703901 -0.7574801069507988" rpy="0 0 0"/>
    <geometry>
      <mesh filename="package://meshes/UR_Hand_1v3_1.stl" scale="1.0 1.0 1.0"/>
    </geometry>
    <material name="silver"/>
  </visual>
  <collision>
    <origin xyz="-0.11532232994676837 0.3182746084703901 -0.7574801069507988" rpy="0 0 0"/>
    <geometry>
      <mesh filename="package://meshes/UR_Hand_1v3_1.stl" scale="1.0 1.0 1.0"/>
    </geometry>
  </collision>
</link>

<link name="U_Neck_1v4_1">
  <inertial>
    <origin xyz="-0.0003721026714716835 -0.0021747031994796425 0.02576223015528086" rpy="0 0 0"/>
    <mass value="0.40364564128614283"/>
    <inertia ixx="98201871.513498" iyy="98410547.46288" izz="241766.942944" ixy="-372.492156" iyz="-7748.882081" ixz="-4634879.217493"/>
  </inertial>
  <visual>
    <origin xyz="-0.07400000000094624 -0.0023005000000187125 -1.5338999999999998" rpy="0 0 0"/>
    <geometry>
      <mesh filename="package://meshes/U_Neck_1v4_1.stl" scale="1.0 1.0 1.0"/>
    </geometry>
    <material name="silver"/>
  </visual>
  <collision>
    <origin xyz="-0.07400000000094624 -0.0023005000000187125 -1.5338999999999998" rpy="0 0 0"/>
    <geometry>
      <mesh filename="package://meshes/U_Neck_1v4_1.stl" scale="1.0 1.0 1.0"/>
    </geometry>
  </collision>
</link>

<link name="LL_Hip_1v5_1">
  <inertial>
    <origin xyz="-0.06917669367320742 1.068634803136348e-06 -0.06802628174919562" rpy="0 0 0"/>
    <mass value="2.679330855492574"/>
    <inertia ixx="206825057.818037" iyy="204832597.376779" izz="4258880.580828" ixy="-1146194.739839" iyz="-24457123.087761" ixz="-9768174.675569"/>
  </inertial>
  <visual>
    <origin xyz="-0.11000000000059271 -0.10480050000000717 -0.9390999999999983" rpy="0 0 0"/>
    <geometry>
      <mesh filename="package://meshes/LL_Hip_1v5_1.stl" scale="1.0 1.0 1.0"/>
    </geometry>
    <material name="silver"/>
  </visual>
  <collision>
    <origin xyz="-0.11000000000059271 -0.10480050000000717 -0.9390999999999983" rpy="0 0 0"/>
    <geometry>
      <mesh filename="package://meshes/LL_Hip_1v5_1.stl" scale="1.0 1.0 1.0"/>
    </geometry>
  </collision>
</link>

<link name="LL_Hip_2v4_1">
  <inertial>
    <origin xyz="0.04938812120643846 -0.002454495988455214 6.441357592052555e-05" rpy="0 0 0"/>
    <mass value="2.6278046422077392"/>
    <inertia ixx="194774524.635037" iyy="195100036.413925" izz="6121476.48038" ixy="-2886180.566598" iyz="-22970592.830384" ixz="-24102077.707164"/>
  </inertial>
  <visual>
    <origin xyz="-0.058000000000593153 -0.10480050000000508 -0.8540999999999983" rpy="0 0 0"/>
    <geometry>
      <mesh filename="package://meshes/LL_Hip_2v4_1.stl" scale="1.0 1.0 1.0"/>
    </geometry>
    <material name="silver"/>
  </visual>
  <collision>
    <origin xyz="-0.058000000000593153 -0.10480050000000508 -0.8540999999999983" rpy="0 0 0"/>
    <geometry>
      <mesh filename="package://meshes/LL_Hip_2v4_1.stl" scale="1.0 1.0 1.0"/>
    </geometry>
  </collision>
</link>

<link name="LL_Hip_3v5_1">
  <inertial>
    <origin xyz="-0.0002922148222425314 0.044721951547469725 -0.24721488423935306" rpy="0 0 0"/>
    <mass value="5.64595764653467"/>
    <inertia ixx="222134283.686691" iyy="222674491.004629" izz="14076978.436312" ixy="-6531657.370596" iyz="-36307734.440104" ixz="-37514946.571729"/>
  </inertial>
  <visual>
    <origin xyz="-0.1100000000005928 -0.06080050000000463 -0.8540999999999993" rpy="0 0 0"/>
    <geometry>
      <mesh filename="package://meshes/LL_Hip_3v5_1.stl" scale="1.0 1.0 1.0"/>
    </geometry>
    <material name="silver"/>
  </visual>
  <collision>
    <origin xyz="-0.1100000000005928 -0.06080050000000463 -0.8540999999999993" rpy="0 0 0"/>
    <geometry>
      <mesh filename="package://meshes/LL_Hip_3v5_1.stl" scale="1.0 1.0 1.0"/>
    </geometry>
  </collision>
</link>

<link name="LL_Knee_1v4_1">
  <inertial>
    <origin xyz="0.007025018161256788 0.04906374764128282 -0.168461411231459" rpy="0 0 0"/>
    <mass value="2.6111042033255614"/>
    <inertia ixx="35454125.575595" iyy="35784433.230535" izz="7259375.237703" ixy="-3352158.27768" iyz="-9650856.301445" ixz="-10273160.135679"/>
  </inertial>
  <visual>
    <origin xyz="-0.10998795286076188 -0.060800499999995546 -0.5041000002073353" rpy="0 0 0"/>
    <geometry>
      <mesh filename="package://meshes/LL_Knee_1v4_1.stl" scale="1.0 1.0 1.0"/>
    </geometry>
    <material name="silver"/>
  </visual>
  <collision>
    <origin xyz="-0.10998795286076188 -0.060800499999995546 -0.5041000002073353" rpy="0 0 0"/>
    <geometry>
      <mesh filename="package://meshes/LL_Knee_1v4_1.stl" scale="1.0 1.0 1.0"/>
    </geometry>
  </collision>
</link>

<link name="LL_Ankle_1v4_1">
  <inertial>
    <origin xyz="-0.0022748541511046837 0.04339536276981636 -5.943449598930783e-05" rpy="0 0 0"/>
    <mass value="2.8327660907109085"/>
    <inertia ixx="10151041.681159" iyy="10411925.122937" izz="6758471.434986" ixy="-3178579.810095" iyz="-4545759.816714" ixz="-4699465.024495"/>
  </inertial>
  <visual>
    <origin xyz="-0.10998795286076547 -0.06080049999999599 -0.1541000002073367" rpy="0 0 0"/>
    <geometry>
      <mesh filename="package://meshes/LL_Ankle_1v4_1.stl" scale="1.0 1.0 1.0"/>
    </geometry>
    <material name="silver"/>
  </visual>
  <collision>
    <origin xyz="-0.10998795286076547 -0.06080049999999599 -0.1541000002073367" rpy="0 0 0"/>
    <geometry>
      <mesh filename="package://meshes/LL_Ankle_1v4_1.stl" scale="1.0 1.0 1.0"/>
    </geometry>
  </collision>
</link>

<link name="LL_Ankle_2v7_1">
  <inertial>
    <origin xyz="-0.01909895779530663 9.91404423666431e-05 -0.00951381534407675" rpy="0 0 0"/>
    <mass value="2.0994891576983727"/>
    <inertia ixx="7093850.655066" iyy="5516216.053076" izz="3295694.52495" ixy="-777362.896177" iyz="-3184531.556344" ixz="-884043.160266"/>
  </inertial>
  <visual>
    <origin xyz="-0.05448795286076588 -0.10480049999999587 -0.15410000020733483" rpy="0 0 0"/>
    <geometry>
      <mesh filename="package://meshes/LL_Ankle_2v7_1.stl" scale="1.0 1.0 1.0"/>
    </geometry>
    <material name="silver"/>
  </visual>
  <collision>
    <origin xyz="-0.05448795286076588 -0.10480049999999587 -0.15410000020733483" rpy="0 0 0"/>
    <geometry>
      <mesh filename="package://meshes/LL_Ankle_2v7_1.stl" scale="1.0 1.0 1.0"/>
    </geometry>
  </collision>
</link>

<link name="LR_Hip_1v2_1">
  <inertial>
    <origin xyz="-0.06917669367320727 1.0686348031896388e-06 -0.06802628174919562" rpy="0 0 0"/>
    <mass value="2.679330855492574"/>
    <inertia ixx="206572249.883131" iyy="204832597.376781" izz="4006072.645919" ixy="1095853.490372" iyz="23382933.587843" ixz="-9768174.675569"/>
  </inertial>
  <visual>
    <origin xyz="-0.11000000000059132 0.10019949999999271 -0.9391000000000024" rpy="0 0 0"/>
    <geometry>
      <mesh filename="package://meshes/LR_Hip_1v2_1.stl" scale="1.0 1.0 1.0"/>
    </geometry>
    <material name="silver"/>
  </visual>
  <collision>
    <origin xyz="-0.11000000000059132 0.10019949999999271 -0.9391000000000024" rpy="0 0 0"/>
    <geometry>
      <mesh filename="package://meshes/LR_Hip_1v2_1.stl" scale="1.0 1.0 1.0"/>
    </geometry>
  </collision>
</link>

<link name="LR_Hip_2v3_1">
  <inertial>
    <origin xyz="0.04938812120643871 0.002454495988455179 -6.441357592038344e-05" rpy="0 0 0"/>
    <mass value="2.6278046422077392"/>
    <inertia ixx="194474805.8566" iyy="195042214.060118" izz="5879580.05575" ixy="2756355.629313" iyz="21933578.993968" ixz="-24097652.322983"/>
  </inertial>
  <visual>
    <origin xyz="-0.05800000000059195 0.10019949999999474 -0.8541000000000024" rpy="0 0 0"/>
    <geometry>
      <mesh filename="package://meshes/LR_Hip_2v3_1.stl" scale="1.0 1.0 1.0"/>
    </geometry>
    <material name="silver"/>
  </visual>
  <collision>
    <origin xyz="-0.05800000000059195 0.10019949999999474 -0.8541000000000024" rpy="0 0 0"/>
    <geometry>
      <mesh filename="package://meshes/LR_Hip_2v3_1.stl" scale="1.0 1.0 1.0"/>
    </geometry>
  </collision>
</link>

<link name="LR_Hip_3v5_1">
  <inertial>
    <origin xyz="-0.00029967114549283024 -0.04466562217330099 -0.24713811091901852" rpy="0 0 0"/>
    <mass value="5.650175369841302"/>
    <inertia ixx="221819410.390794" iyy="222901978.179955" izz="13543329.68625" ixy="6255314.799964" iyz="34741317.876425" ixz="-37544589.250961"/>
  </inertial>
  <visual>
    <origin xyz="-0.11000000000059233 0.056199499999994365 -0.8541000000000014" rpy="0 0 0"/>
    <geometry>
      <mesh filename="package://meshes/LR_Hip_3v5_1.stl" scale="1.0 1.0 1.0"/>
    </geometry>
    <material name="silver"/>
  </visual>
  <collision>
    <origin xyz="-0.11000000000059233 0.056199499999994365 -0.8541000000000014" rpy="0 0 0"/>
    <geometry>
      <mesh filename="package://meshes/LR_Hip_3v5_1.stl" scale="1.0 1.0 1.0"/>
    </geometry>
  </collision>
</link>

<link name="LR_Knee_1v6_1">
  <inertial>
    <origin xyz="0.007017904177470058 -0.045408339029957806 -0.16864509775564826" rpy="0 0 0"/>
    <mass value="2.613749432885655"/>
    <inertia ixx="34999994.617706" iyy="35794194.010197" izz="6802120.853605" ixy="3106888.153142" iyz="8936566.636069" ixz="-10277591.159117"/>
  </inertial>
  <visual>
    <origin xyz="-0.10998735043189824 0.0561995000000012 -0.5041000002073385" rpy="0 0 0"/>
    <geometry>
      <mesh filename="package://meshes/LR_Knee_1v6_1.stl" scale="1.0 1.0 1.0"/>
    </geometry>
    <material name="silver"/>
  </visual>
  <collision>
    <origin xyz="-0.10998735043189824 0.0561995000000012 -0.5041000002073385" rpy="0 0 0"/>
    <geometry>
      <mesh filename="package://meshes/LR_Knee_1v6_1.stl" scale="1.0 1.0 1.0"/>
    </geometry>
  </collision>
</link>

<link name="LR_Ankle_1v2_1">
  <inertial>
    <origin xyz="-0.0022748541512804723 -0.04339536276981634 5.837972197713981e-05" rpy="0 0 0"/>
    <mass value="2.8327660907109085"/>
    <inertia ixx="9895741.284996" iyy="10422173.205342" izz="6492849.437267" ixy="3038188.375536" iyz="4349315.675225" ixz="-4703519.161885"/>
  </inertial>
  <visual>
    <origin xyz="-0.10998735043190161 0.056199500000013 -0.1541000002073434" rpy="0 0 0"/>
    <geometry>
      <mesh filename="package://meshes/LR_Ankle_1v2_1.stl" scale="1.0 1.0 1.0"/>
    </geometry>
    <material name="silver"/>
  </visual>
  <collision>
    <origin xyz="-0.10998735043190161 0.056199500000013 -0.1541000002073434" rpy="0 0 0"/>
    <geometry>
      <mesh filename="package://meshes/LR_Ankle_1v2_1.stl" scale="1.0 1.0 1.0"/>
    </geometry>
  </collision>
</link>

<link name="LR_Ankle_2v3_1">
  <inertial>
    <origin xyz="-0.019046655278615838 9.967099675103342e-05 -0.009558695795511109" rpy="0 0 0"/>
    <mass value="2.0896905636222005"/>
    <inertia ixx="6854130.407945" iyy="5492021.229086" izz="3078405.67316" ixy="743217.903146" iyz="3022631.231704" ixz="-880363.039798"/>
  </inertial>
  <visual>
    <origin xyz="-0.054487350431901324 0.10019950000001311 -0.15410000020734305" rpy="0 0 0"/>
    <geometry>
      <mesh filename="package://meshes/LR_Ankle_2v3_1.stl" scale="1.0 1.0 1.0"/>
    </geometry>
    <material name="silver"/>
  </visual>
  <collision>
    <origin xyz="-0.054487350431901324 0.10019950000001311 -0.15410000020734305" rpy="0 0 0"/>
    <geometry>
      <mesh filename="package://meshes/LR_Ankle_2v3_1.stl" scale="1.0 1.0 1.0"/>
    </geometry>
  </collision>
</link>

<link name="U_Neck_2_simv5_1">
  <inertial>
    <origin xyz="0.03715460305593434 -0.03828793184364124 0.07079294389298213" rpy="0 0 0"/>
    <mass value="1.4175125769096264"/>
    <inertia ixx="378386744.327795" iyy="380553107.631774" izz="2766658.367458" ixy="-33188.188593" iyz="-351779.980523" ixz="-25458619.156587"/>
  </inertial>
  <visual>
    <origin xyz="-0.07400000000094514 -0.03980050000001769 -1.561400000000001" rpy="0 0 0"/>
    <geometry>
      <mesh filename="package://meshes/U_Neck_2_simv5_1.stl" scale="1.0 1.0 1.0"/>
    </geometry>
    <material name="silver"/>
  </visual>
  <collision>
    <origin xyz="-0.07400000000094514 -0.03980050000001769 -1.561400000000001" rpy="0 0 0"/>
    <geometry>
      <mesh filename="package://meshes/U_Neck_2_simv5_1.stl" scale="1.0 1.0 1.0"/>
    </geometry>
  </collision>
</link>

<link name="LR_Footv2_2">
  <inertial>
    <origin xyz="0.014369982408760454 8.110878130562326e-05 -0.04063409404472774" rpy="0 0 0"/>
    <mass value="2.350132620082288"/>
    <inertia ixx="2960136.708995" iyy="5260637.541608" izz="7521832.041525" ixy="2964599.898857" iyz="787548.145742" ixz="-937790.499778"/>
  </inertial>
  <visual>
    <origin xyz="-0.11168735043190177 0.10019950000001462 -0.07410000020734382" rpy="0 0 0"/>
    <geometry>
      <mesh filename="package://meshes/LR_Footv2_2.stl" scale="1.0 1.0 1.0"/>
    </geometry>
    <material name="silver"/>
  </visual>
  <collision>
    <origin xyz="-0.11168735043190177 0.10019950000001462 -0.07410000020734382" rpy="0 0 0"/>
    <geometry>
      <mesh filename="package://meshes/LR_Footv2_2.stl" scale="1.0 1.0 1.0"/>
    </geometry>
  </collision>
</link>

<link name="LL_Footv1_1">
  <inertial>
    <origin xyz="0.014369982408760204 8.110878130750621e-05 -0.04063409404472829" rpy="0 0 0"/>
    <mass value="2.350132620082288"/>
    <inertia ixx="3189594.716792" iyy="5260673.232209" izz="7751325.739923" ixy="-3107962.356339" iyz="-824601.63669" ixz="-937795.237366"/>
  </inertial>
  <visual>
    <origin xyz="-0.11168795286077413 -0.10480049999999647 -0.0741000002073353" rpy="0 0 0"/>
    <geometry>
      <mesh filename="package://meshes/LL_Footv1_1.stl" scale="1.0 1.0 1.0"/>
    </geometry>
    <material name="silver"/>
  </visual>
  <collision>
    <origin xyz="-0.11168795286077413 -0.10480049999999647 -0.0741000002073353" rpy="0 0 0"/>
    <geometry>
      <mesh filename="package://meshes/LL_Footv1_1.stl" scale="1.0 1.0 1.0"/>
    </geometry>
  </collision>
</link>

<link name="UL_Arm_1v1_1">
  <inertial>
    <origin xyz="-0.01986070587217043 -0.011871163938562362 -0.11195471605184182" rpy="0 0 0"/>
    <mass value="0.5866932106262186"/>
    <inertia ixx="90877199.312267" iyy="86604901.907999" izz="5899175.92214" ixy="-1953063.973129" iyz="-20835164.780939" ixz="-8047390.524491"/>
  </inertial>
  <visual>
    <origin xyz="-0.13300000000093865 -0.30540050000001434 -1.318799999999995" rpy="0 0 0"/>
    <geometry>
      <mesh filename="package://meshes/UL_Arm_1v1_1.stl" scale="1.0 1.0 1.0"/>
    </geometry>
    <material name="silver"/>
  </visual>
  <collision>
    <origin xyz="-0.13300000000093865 -0.30540050000001434 -1.318799999999995" rpy="0 0 0"/>
    <geometry>
      <mesh filename="package://meshes/UL_Arm_1v1_1.stl" scale="1.0 1.0 1.0"/>
    </geometry>
  </collision>
</link>

<link name="UL_Arm_3v1_1">
  <inertial>
    <origin xyz="-0.016384028005943813 -0.0006831003240946388 -0.0769948468007641" rpy="0 0 0"/>
    <mass value="0.4103279308573677"/>
    <inertia ixx="37867521.67358" iyy="34680897.190908" izz="4405881.583661" ixy="-1466099.17871" iyz="-11328577.69798" ixz="-4419658.986563"/>
  </inertial>
  <visual>
    <origin xyz="-0.13430000000093795 -0.3043084455622975 -0.9865211472132753" rpy="0 0 0"/>
    <geometry>
      <mesh filename="package://meshes/UL_Arm_3v1_1.stl" scale="1.0 1.0 1.0"/>
    </geometry>
    <material name="silver"/>
  </visual>
  <collision>
    <origin xyz="-0.13430000000093795 -0.3043084455622975 -0.9865211472132753" rpy="0 0 0"/>
    <geometry>
      <mesh filename="package://meshes/UL_Arm_3v1_1.stl" scale="1.0 1.0 1.0"/>
    </geometry>
  </collision>
</link>

<link name="UL_Wrist_1v1_1">
  <inertial>
    <origin xyz="-0.03425367007792584 0.0012798145617670187 -0.024730881320236053" rpy="0 0 0"/>
    <mass value="0.7829866998307424"/>
    <inertia ixx="59712760.70401" iyy="53935308.456626" izz="8768504.952357" ixy="-3265800.730954" iyz="-19487657.985266" ixz="-8767815.322266"/>
  </inertial>
  <visual>
    <origin xyz="-0.17129999947641764 -0.303053569757628 -0.8427266226766474" rpy="0 0 0"/>
    <geometry>
      <mesh filename="package://meshes/UL_Wrist_1v1_1.stl" scale="1.0 1.0 1.0"/>
    </geometry>
    <material name="silver"/>
  </visual>
  <collision>
    <origin xyz="-0.17129999947641764 -0.303053569757628 -0.8427266226766474" rpy="0 0 0"/>
    <geometry>
      <mesh filename="package://meshes/UL_Wrist_1v1_1.stl" scale="1.0 1.0 1.0"/>
    </geometry>
  </collision>
</link>

<link name="UL_Wrist_2v1_1">
  <inertial>
    <origin xyz="1.0526813198907803e-10 0.031611417342957006 -0.02116686261589436" rpy="0 0 0"/>
    <mass value="0.1188082072163882"/>
    <inertia ixx="8178361.641076" iyy="7354823.966132" izz="1308763.664051" ixy="-502338.131028" iyz="-2740846.48735" ixz="-1303033.143015"/>
  </inertial>
  <visual>
    <origin xyz="-0.14179999947640684 -0.26659494489671803 -0.7946951884564168" rpy="0 0 0"/>
    <geometry>
      <mesh filename="package://meshes/UL_Wrist_2v1_1.stl" scale="1.0 1.0 1.0"/>
    </geometry>
    <material name="silver"/>
  </visual>
  <collision>
    <origin xyz="-0.14179999947640684 -0.26659494489671803 -0.7946951884564168" rpy="0 0 0"/>
    <geometry>
      <mesh filename="package://meshes/UL_Wrist_2v1_1.stl" scale="1.0 1.0 1.0"/>
    </geometry>
  </collision>
</link>

<link name="UL_Arm_2v1_1">
  <inertial>
    <origin xyz="-0.029190769494796563 0.01722170119188835 -0.05184754157022752" rpy="0 0 0"/>
    <mass value="1.9252498488611527"/>
    <inertia ixx="233097115.018869" iyy="220354827.127298" izz="19891374.293382" ixy="-7526987.335842" iyz="-59055329.3121" ixz="-27513414.956138"/>
  </inertial>
  <visual>
    <origin xyz="-0.16400000000093784 -0.2729005000000102 -1.1117999999999961" rpy="0 0 0"/>
    <geometry>
      <mesh filename="package://meshes/UL_Arm_2v1_1.stl" scale="1.0 1.0 1.0"/>
    </geometry>
    <material name="silver"/>
  </visual>
  <collision>
    <origin xyz="-0.16400000000093784 -0.2729005000000102 -1.1117999999999961" rpy="0 0 0"/>
    <geometry>
      <mesh filename="package://meshes/UL_Arm_2v1_1.stl" scale="1.0 1.0 1.0"/>
    </geometry>
  </collision>
</link>

<joint name="Revolute48" type="revolute">
  <origin xyz="0.11000000000059089 0.002300500000009677 1.0694000000000008" rpy="0 0 0"/>
  <parent link="L_Pelvisv15_1"/>
  <child link="U_Waist_2v8_1"/>
  <axis xyz="8.135850272080565e-15 -2.0311009818474446e-14 -1.0000000000000007"/>
  <limit upper="3.14159" lower="-3.14159" effort="100" velocity="100"/>
</joint>

<joint name="Revolute49" type="revolute">
  <origin xyz="-9.059419880941278e-16 0.05400000000000227 0.084999999999999" rpy="0 0 0"/>
  <parent link="U_Waist_2v8_1"/>
  <child link="U_Waist_1v3_1"/>
  <axis xyz="2.2687301812009516e-15 -0.9999999999999998 2.0304938286308574e-14"/>
  <limit upper="3.14159" lower="-3.14159" effort="100" velocity="100"/>
</joint>

<joint name="Revolute51" type="revolute">
  <origin xyz="-0.06599999999999988 -0.05400000000000014 2.842170943040401e-16" rpy="0 0 0"/>
  <parent link="U_Waist_1v3_1"/>
  <child link="U_Body_1v21_1"/>
  <axis xyz="0.9999999999999999 2.1892483055747788e-15 7.956679769990199e-15"/>
  <limit upper="3.14159" lower="-3.14159" effort="100" velocity="100"/>
</joint>

<joint name="Revolute87" type="revolute">
  <origin xyz="0.08900000000035359 0.15400000000000424 0.22749999999999773" rpy="0 0 0"/>
  <parent link="U_Body_1v21_1"/>
  <child link="UL_Shoulder_1v3_1"/>
  <axis xyz="2.8014773929907452e-15 -2.0085214567129895e-14 -1.0000000000000007"/>
  <limit upper="3.14159" lower="-3.14159" effort="100" velocity="100"/>
</joint>

<joint name="Revolute53" type="revolute">
  <origin xyz="0.08900000000035978 -0.15399999999999658 0.22750000000000511" rpy="0 0 0"/>
  <parent link="U_Body_1v21_1"/>
  <child link="UR_Shoulder_1v3_1"/>
  <axis xyz="2.827717170072879e-15 -2.0147078449994638e-14 -1.0"/>
  <limit upper="3.14159" lower="-3.14159" effort="100" velocity="100"/>
</joint>

<joint name="Revolute54" type="revolute">
  <origin xyz="3.552713678800501e-17 -0.03409999999999945 0.06499999999999971" rpy="0 0 0"/>
  <parent link="UR_Shoulder_1v3_1"/>
  <child link="UR_Shoulder_2v2_1"/>
  <axis xyz="-2.1206546230909074e-14 0.9999999999999996 -2.0424634206150927e-14"/>
  <limit upper="3.14159" lower="-3.14159" effort="100" velocity="100"/>
</joint>

<joint name="Revolute55" type="revolute">
  <origin xyz="0.03290000000000236 -0.11499999999999976 1.7053025658242404e-15" rpy="0 0 0"/>
  <parent link="UR_Shoulder_2v2_1"/>
  <child link="UR_Shoulder_3v2_1"/>
  <axis xyz="0.9999999999999996 2.1170394272997545e-14 3.0403507408677246e-15"/>
  <limit upper="3.14159" lower="-3.14159" effort="100" velocity="100"/>
</joint>

<joint name="Revolute88" type="revolute">
  <origin xyz="-0.03290000000000072 -3.0908609005564358e-15 -0.1281000000000023" rpy="0 0 0"/>
  <parent link="UR_Shoulder_3v2_1"/>
  <child link="UR_Arm_1v2_1"/>
  <axis xyz="-2.74242071822312e-15 2.05391259555654e-14 1.000000000000006"/>
  <limit upper="3.14159" lower="-3.14159" effort="100" velocity="100"/>
</joint>

<joint name="Revolute89" type="revolute">
  <origin xyz="0.030999999999999927 0.03249999999999698 -0.20700000000000005" rpy="0 0 0"/>
  <parent link="UR_Arm_1v2_1"/>
  <child link="UR_Arm_2v6_1"/>
  <axis xyz="0.9999999999999992 1.8403237546193293e-14 2.7749021298199084e-15"/>
  <limit upper="3.14159" lower="-3.14159" effort="100" velocity="100"/>
</joint>

<joint name="Revolute58" type="revolute">
  <origin xyz="-0.030999999999998983 -0.03250000000000369 -0.12499999999999901" rpy="0 0 0"/>
  <parent link="UR_Arm_2v6_1"/>
  <child link="UR_Arm_3v3_1"/>
  <axis xyz="2.788026642422156e-15 -2.1860985244259824e-14 -0.9999999999999994"/>
  <limit upper="3.14159" lower="-3.14159" effort="100" velocity="100"/>
</joint>

<joint name="Revolute90" type="revolute">
  <origin xyz="-9.769962616701378e-16 0.034100000000000213 0.06499999999999914" rpy="0 0 0"/>
  <parent link="UL_Shoulder_1v3_1"/>
  <child link="UL_Shoulder_2v3_1"/>
  <axis xyz="2.100834753095154e-14 -0.9999999999999998 2.0046464488387983e-14"/>
  <limit upper="3.14159" lower="-3.14159" effort="100" velocity="100"/>
</joint>

<joint name="Revolute91" type="revolute">
  <origin xyz="0.03729999999999738 0.11500000000000121 -1.9895196601282807e-15" rpy="0 0 0"/>
  <parent link="UL_Shoulder_2v3_1"/>
  <child link="UL_Shoulder_3v3_1"/>
  <axis xyz="-0.9999999999999997 -2.1042733972000734e-14 -3.3863255073556605e-15"/>
  <limit upper="3.14159" lower="-3.14159" effort="100" velocity="100"/>
</joint>

<joint name="Revolute97" type="revolute">
  <origin xyz="0.036999999475479765 0.00012699995041472788 -0.14379988777908267" rpy="0 0 0"/>
  <parent link="UR_Arm_3v3_1"/>
  <child link="UR_Wrist_1v6_1"/>
  <axis xyz="-0.9999999999999968 2.6758882414044968e-14 -2.6862173811482373e-15"/>
  <limit upper="3.14159" lower="-3.14159" effort="100" velocity="100"/>
</joint>

<joint name="Revolute99" type="revolute">
  <origin xyz="-0.0370000000000014 -0.029957574082523877 -0.048026490139191934" rpy="0 0 0"/>
  <parent link="UR_Wrist_1v6_1"/>
  <child link="UR_Wrist_2v3_1"/>
  <axis xyz="2.4983527351433608e-14 0.9999996095995696 0.0008836292804400916"/>
  <limit upper="3.14159" lower="-3.14159" effort="100" velocity="100"/>
</joint>

<joint name="Rigid71" type="fixed">
  <origin xyz="-0.01767766952966248 0.01235546566171287 -0.03749351513093174" rpy="0 0 0"/>
  <parent link="UR_Wrist_2v3_1"/>
  <child link="UR_Hand_1v3_1"/>
</joint>

<joint name="Revolute72" type="revolute">
  <origin xyz="0.030000000000356124 6.906142324680786e-15 0.3794999999999999" rpy="0 0 0"/>
  <parent link="U_Body_1v21_1"/>
  <child link="U_Neck_1v4_1"/>
  <axis xyz="-2.787114617897265e-15 1.6382728507124966e-14 1.0000000000000016"/>
  <limit upper="3.14159" lower="-3.14159" effort="100" velocity="100"/>
</joint>

<joint name="Revolute74" type="revolute">
  <origin xyz="0.11000000000059271 0.10480050000000717 0.9390999999999983" rpy="0 0 0"/>
  <parent link="L_Pelvisv15_1"/>
  <child link="LL_Hip_1v5_1"/>
  <axis xyz="-7.546779104011179e-15 2.0227461892159993e-14 1.0000000000000007"/>
  <limit upper="3.14159" lower="-3.14159" effort="100" velocity="100"/>
</joint>

<joint name="Revolute76" type="revolute">
  <origin xyz="-0.05199999999999955 -2.078337502098293e-15 -0.085" rpy="0 0 0"/>
  <parent link="LL_Hip_1v5_1"/>
  <child link="LL_Hip_2v4_1"/>
  <axis xyz="-0.9999999999999997 7.225358918441863e-15 -7.0862724607024596e-15"/>
  <limit upper="3.14159" lower="-3.14159" effort="100" velocity="100"/>
</joint>

<joint name="Revolute77" type="revolute">
  <origin xyz="0.05199999999999966 -0.044000000000000455 9.947598300641404e-16" rpy="0 0 0"/>
  <parent link="LL_Hip_2v4_1"/>
  <child link="LL_Hip_3v5_1"/>
  <axis xyz="7.197603342826392e-15 0.9999999999999997 -2.022080419772369e-14"/>
  <limit upper="3.14159" lower="-3.14159" effort="100" velocity="100"/>
</joint>

<joint name="Revolute104" type="revolute">
  <origin xyz="-1.2047139830926313e-05 -9.086065233532282e-15 -0.34999999979266405" rpy="0 0 0"/>
  <parent link="LL_Hip_3v5_1"/>
  <child link="LL_Knee_1v4_1"/>
  <axis xyz="5.822484644674764e-15 0.9999999999999996 3.9291486730870894e-16"/>
  <limit upper="3.14159" lower="-3.14159" effort="100" velocity="100"/>
</joint>

<joint name="Revolute79" type="revolute">
  <origin xyz="3.588240815588506e-15 4.440892098500626e-16 -0.34999999999999853" rpy="0 0 0"/>
  <parent link="LL_Knee_1v4_1"/>
  <child link="LL_Ankle_1v4_1"/>
  <axis xyz="5.822484644674758e-15 0.9999999999999984 3.9268575288735353e-16"/>
  <limit upper="3.14159" lower="-3.14159" effort="100" velocity="100"/>
</joint>

<joint name="Revolute105" type="revolute">
  <origin xyz="-0.05549999999999959 0.04399999999999988 -1.8474111129762605e-15" rpy="0 0 0"/>
  <parent link="LL_Ankle_1v4_1"/>
  <child link="LL_Ankle_2v7_1"/>
  <axis xyz="-0.9999999999999997 5.850240220290362e-15 -1.0861470584410102e-14"/>
  <limit upper="3.14159" lower="-3.14159" effort="100" velocity="100"/>
</joint>

<joint name="Revolute100" type="revolute">
  <origin xyz="0.11000000000059132 -0.10019949999999271 0.9391000000000024" rpy="0 0 0"/>
  <parent link="L_Pelvisv15_1"/>
  <child link="LR_Hip_1v2_1"/>
  <axis xyz="-8.753459365229937e-15 2.0227461892159993e-14 1.0000000000000007"/>
  <limit upper="3.14159" lower="-3.14159" effort="100" velocity="100"/>
</joint>

<joint name="Revolute101" type="revolute">
  <origin xyz="-0.051999999999999366 -2.0250467969162858e-15 -0.085" rpy="0 0 0"/>
  <parent link="LR_Hip_1v2_1"/>
  <child link="LR_Hip_2v3_1"/>
  <axis xyz="-0.9999999999999997 7.225358918441806e-15 -9.658055218389e-15"/>
  <limit upper="3.14159" lower="-3.14159" effort="100" velocity="100"/>
</joint>

<joint name="Revolute83" type="revolute">
  <origin xyz="0.05200000000000038 0.04400000000000038 -9.947598300641404e-16" rpy="0 0 0"/>
  <parent link="LR_Hip_2v3_1"/>
  <child link="LR_Hip_3v5_1"/>
  <axis xyz="-7.197603342826392e-15 -0.9999999999999997 2.0343102202780055e-14"/>
  <limit upper="3.14159" lower="-3.14159" effort="100" velocity="100"/>
</joint>

<joint name="Revolute102" type="revolute">
  <origin xyz="-1.2649568694094172e-05 -6.8389738316909644e-15 -0.34999999979266294" rpy="0 0 0"/>
  <parent link="LR_Hip_3v5_1"/>
  <child link="LR_Knee_1v6_1"/>
  <axis xyz="-7.136371002869012e-15 -0.9999999999999997 2.0154017343898583e-14"/>
  <limit upper="3.14159" lower="-3.14159" effort="100" velocity="100"/>
</joint>

<joint name="Revolute103" type="revolute">
  <origin xyz="3.375077994860476e-15 -1.1803891197814665e-14 -0.34999999999999504" rpy="0 0 0"/>
  <parent link="LR_Knee_1v6_1"/>
  <child link="LR_Ankle_1v2_1"/>
  <axis xyz="7.524949061487823e-15 0.9999999999999962 -2.1083600012600796e-14"/>
  <limit upper="3.14159" lower="-3.14159" effort="100" velocity="100"/>
</joint>

<joint name="Revolute106" type="revolute">
  <origin xyz="-0.055500000000000285 -0.0440000000000001 -3.552713678800501e-16" rpy="0 0 0"/>
  <parent link="LR_Ankle_1v2_1"/>
  <child link="LR_Ankle_2v3_1"/>
  <axis xyz="-0.9999999999999997 7.552704637103256e-15 -9.569493538879027e-15"/>
  <limit upper="3.14159" lower="-3.14159" effort="100" velocity="100"/>
</joint>

<joint name="Revolute107" type="revolute">
  <origin xyz="-1.092459456231154e-15 0.03749999999999897 0.027500000000001138" rpy="0 0 0"/>
  <parent link="U_Neck_1v4_1"/>
  <child link="U_Neck_2_simv5_1"/>
  <axis xyz="1.9735531699801058e-14 -1.000000000000001 1.7420093145759097e-14"/>
  <limit upper="3.14159" lower="-3.14159" effort="100" velocity="100"/>
</joint>

<joint name="Rigid111" type="fixed">
  <origin xyz="0.057200000000000445 -1.5099033134902129e-15 -0.07999999999999922" rpy="0 0 0"/>
  <parent link="LR_Ankle_2v3_1"/>
  <child link="LR_Footv2_2"/>
</joint>

<joint name="Rigid113" type="fixed">
  <origin xyz="0.057200000000008244 6.039613253960852e-16 -0.07999999999999953" rpy="0 0 0"/>
  <parent link="LL_Ankle_2v7_1"/>
  <child link="LL_Footv1_1"/>
</joint>

<joint name="Revolute114" type="revolute">
  <origin xyz="-0.03730000000000144 -3.126388037344441e-15 -0.12809999999999974" rpy="0 0 0"/>
  <parent link="UL_Shoulder_3v3_1"/>
  <child link="UL_Arm_1v1_1"/>
  <axis xyz="3.0461818205712783e-15 1.999442278410868e-14 1.000000000000001"/>
  <limit upper="3.14159" lower="-3.14159" effort="100" velocity="100"/>
</joint>

<joint name="Revolute116" type="revolute">
  <origin xyz="-0.0296999999999999 0.03140794556228734 -0.12527885278672074" rpy="0 0 0"/>
  <parent link="UL_Arm_2v1_1"/>
  <child link="UL_Arm_3v1_1"/>
  <axis xyz="-2.417068170382385e-15 0.008726535498401798 0.9999619230641716"/>
  <limit upper="3.14159" lower="-3.14159" effort="100" velocity="100"/>
</joint>

<joint name="Revolute118" type="revolute">
  <origin xyz="0.03699999947547971 -0.0012548758046695596 -0.14379452453662794" rpy="0 0 0"/>
  <parent link="UL_Arm_3v1_1"/>
  <child link="UL_Wrist_1v1_1"/>
  <axis xyz="0.9999999999999996 3.6607934209678794e-14 2.058999505931722e-15"/>
  <limit upper="3.14159" lower="-3.14159" effort="100" velocity="100"/>
</joint>

<joint name="Revolute119" type="revolute">
  <origin xyz="-0.029500000000010813 -0.03645862486090994 -0.048031434220230554" rpy="0 0 0"/>
  <parent link="UL_Wrist_1v1_1"/>
  <child link="UL_Wrist_2v1_1"/>
  <axis xyz="3.753430374577826e-14 -0.999999628736703 -0.0008616997498676732"/>
  <limit upper="3.14159" lower="-3.14159" effort="100" velocity="100"/>
</joint>

<joint name="Revolute120" type="revolute">
  <origin xyz="0.03099999999999918 -0.03250000000000412 -0.20699999999999905" rpy="0 0 0"/>
  <parent link="UL_Arm_1v1_1"/>
  <child link="UL_Arm_2v1_1"/>
  <axis xyz="-0.9999999999999997 5.416975350918763e-15 2.915232109023415e-15"/>
  <limit upper="3.14159" lower="-3.14159" effort="100" velocity="100"/>
</joint>

</robot>
