<?xml version="1.0" ?>
<robot name="FullBody">

<material name="silver">
  <color rgba="0.700 0.700 0.700 1.000"/>
</material>

<link name="L_Pelvisv15_1">
  <inertial>
    <origin xyz="0.07850337576520562 -0.00016609111391420304 0.043105574933707265" rpy="0 0 0"/>
    <mass value="12.902041905941699"/>
    <inertia ixx="0.113288" iyy="0.05846" izz="0.14224" ixy="-0.00012" iyz="-4.9e-05" ixz="-0.005613"/>
  </inertial>
  <visual>
    <origin xyz="0 0 0" rpy="0 0 0"/>
    <geometry>
      <mesh filename="package://meshes/L_Pelvisv15_1.stl" scale="0.001 0.001 0.001"/>
    </geometry>
    <material name="silver"/>
  </visual>
  <collision>
    <origin xyz="0 0 0" rpy="0 0 0"/>
    <geometry>
      <mesh filename="package://meshes/L_Pelvisv15_1.stl" scale="0.001 0.001 0.001"/>
    </geometry>
  </collision>
</link>

<link name="U_Waist_2v8_1">
  <inertial>
    <origin xyz="-0.03373461207010171 -0.0007668257484067517 0.04639506318222689" rpy="0 0 0"/>
    <mass value="6.477060726069988"/>
    <inertia ixx="0.066568" iyy="0.02504" izz="0.080228" ixy="0.000159" iyz="0.000325" ixz="0.000133"/>
  </inertial>
  <visual>
    <origin xyz="-0.11000000000058914 -6.740441538255483e-16 -0.11290049999999863" rpy="0 0 0"/>
    <geometry>
      <mesh filename="package://meshes/U_Waist_2v8_1.stl" scale="0.001 0.001 0.001"/>
    </geometry>
    <material name="silver"/>
  </visual>
  <collision>
    <origin xyz="-0.11000000000058914 -6.740441538255483e-16 -0.11290049999999863" rpy="0 0 0"/>
    <geometry>
      <mesh filename="package://meshes/U_Waist_2v8_1.stl" scale="0.001 0.001 0.001"/>
    </geometry>
  </collision>
</link>

<link name="U_Waist_1v3_1">
  <inertial>
    <origin xyz="-0.0002659373278254551 -0.04482891823085621 4.126265376741545e-06" rpy="0 0 0"/>
    <mass value="3.8814658730154474"/>
    <inertia ixx="0.006439" iyy="0.007393" izz="0.007618" ixy="-1e-05" iyz="-1e-06" ixz="0.0"/>
  </inertial>
  <visual>
    <origin xyz="-0.11000000000058911 -0.05400000000000107 -0.19790049999999834" rpy="0 0 0"/>
    <geometry>
      <mesh filename="package://meshes/U_Waist_1v3_1.stl" scale="0.001 0.001 0.001"/>
    </geometry>
    <material name="silver"/>
  </visual>
  <collision>
    <origin xyz="-0.11000000000058911 -0.05400000000000107 -0.19790049999999834" rpy="0 0 0"/>
    <geometry>
      <mesh filename="package://meshes/U_Waist_1v3_1.stl" scale="0.001 0.001 0.001"/>
    </geometry>
  </collision>
</link>

<link name="U_Body_1v21_1">
  <inertial>
    <origin xyz="0.015154894146993288 0.001762079281842905 0.15771105590623397" rpy="0 0 0"/>
    <mass value="20.033579376135727"/>
    <inertia ixx="0.308968" iyy="0.293536" izz="0.2137" ixy="0.000386" iyz="0.000497" ixz="-0.042223"/>
  </inertial>
  <visual>
    <origin xyz="-0.0440000000005891 -1.103247439145944e-15 -0.1979004999999987" rpy="0 0 0"/>
    <geometry>
      <mesh filename="package://meshes/U_Body_1v21_1.stl" scale="0.001 0.001 0.001"/>
    </geometry>
    <material name="silver"/>
  </visual>
  <collision>
    <origin xyz="-0.0440000000005891 -1.103247439145944e-15 -0.1979004999999987" rpy="0 0 0"/>
    <geometry>
      <mesh filename="package://meshes/U_Body_1v21_1.stl" scale="0.001 0.001 0.001"/>
    </geometry>
  </collision>
</link>

<link name="UR_Shoulder_1v3_1">
  <inertial>
    <origin xyz="4.8688883036912545e-05 -0.004689185127778106 0.059975388405186736" rpy="0 0 0"/>
    <mass value="1.6150479626666572"/>
    <inertia ixx="0.001961" iyy="0.002031" izz="0.001713" ixy="1e-06" iyz="8.2e-05" ixz="-3e-06"/>
  </inertial>
  <visual>
    <origin xyz="-0.13300000000094916 0.1539999999999991 -0.4254004999999993" rpy="0 0 0"/>
    <geometry>
      <mesh filename="package://meshes/UR_Shoulder_1v3_1.stl" scale="0.001 0.001 0.001"/>
    </geometry>
    <material name="silver"/>
  </visual>
  <collision>
    <origin xyz="-0.13300000000094916 0.1539999999999991 -0.4254004999999993" rpy="0 0 0"/>
    <geometry>
      <mesh filename="package://meshes/UR_Shoulder_1v3_1.stl" scale="0.001 0.001 0.001"/>
    </geometry>
  </collision>
</link>

<link name="UR_Shoulder_2v2_1">
  <inertial>
    <origin xyz="-0.0011919891845768027 -0.056404824692319305 1.7398678881397345e-05" rpy="0 0 0"/>
    <mass value="0.4699696793137451"/>
    <inertia ixx="0.0013" iyy="0.00077" izz="0.001461" ixy="-3.8e-05" iyz="-0.0" ixz="0.0"/>
  </inertial>
  <visual>
    <origin xyz="-0.13300000000094994 0.18809999999999874 -0.4904004999999995" rpy="0 0 0"/>
    <geometry>
      <mesh filename="package://meshes/UR_Shoulder_2v2_1.stl" scale="0.001 0.001 0.001"/>
    </geometry>
    <material name="silver"/>
  </visual>
  <collision>
    <origin xyz="-0.13300000000094994 0.18809999999999874 -0.4904004999999995" rpy="0 0 0"/>
    <geometry>
      <mesh filename="package://meshes/UR_Shoulder_2v2_1.stl" scale="0.001 0.001 0.001"/>
    </geometry>
  </collision>
</link>

<link name="UR_Shoulder_3v2_1">
  <inertial>
    <origin xyz="-0.030310314326984472 -0.04860435019477416 -0.0002398741637055779" rpy="0 0 0"/>
    <mass value="2.8349404070306568"/>
    <inertia ixx="0.008564" iyy="0.002739" izz="0.008365" ixy="-0.00034" iyz="2.6e-05" ixz="-4e-06"/>
  </inertial>
  <visual>
    <origin xyz="-0.1659000000009502 0.3030999999999986 -0.4904005" rpy="0 0 0"/>
    <geometry>
      <mesh filename="package://meshes/UR_Shoulder_3v2_1.stl" scale="0.001 0.001 0.001"/>
    </geometry>
    <material name="silver"/>
  </visual>
  <collision>
    <origin xyz="-0.1659000000009502 0.3030999999999986 -0.4904005" rpy="0 0 0"/>
    <geometry>
      <mesh filename="package://meshes/UR_Shoulder_3v2_1.stl" scale="0.001 0.001 0.001"/>
    </geometry>
  </collision>
</link>

<link name="UR_Arm_3v3_1">
  <inertial>
    <origin xyz="-0.016381147407499616 -0.07699258610922566 -9.833802038677897e-05" rpy="0 0 0"/>
    <mass value="0.41026605169868297"/>
    <inertia ixx="0.001446" iyy="0.000531" izz="0.001699" ixy="-0.000194" iyz="2.6e-05" ixz="3e-05"/>
  </inertial>
  <visual>
    <origin xyz="-0.13300000000095027 0.7631999999999995 -0.4904005000000028" rpy="0 0 0"/>
    <geometry>
      <mesh filename="package://meshes/UR_Arm_3v3_1.stl" scale="0.001 0.001 0.001"/>
    </geometry>
    <material name="silver"/>
  </visual>
  <collision>
    <origin xyz="-0.13300000000095027 0.7631999999999995 -0.4904005000000028" rpy="0 0 0"/>
    <geometry>
      <mesh filename="package://meshes/UR_Arm_3v3_1.stl" scale="0.001 0.001 0.001"/>
    </geometry>
  </collision>
</link>

<link name="UR_Hand_1v3_1">
  <inertial>
    <origin xyz="0.020025638546783978 -0.06483653735727579 -0.040780875138455075" rpy="0 0 0"/>
    <mass value="0.31592184802995116"/>
    <inertia ixx="0.001002" iyy="0.000442" izz="0.000684" ixy="-1.1e-05" iyz="-0.000103" ixz="3.6e-05"/>
  </inertial>
  <visual>
    <origin xyz="-0.11532232994676654 0.9925198930492037 -0.5078756084703961" rpy="0 0 0"/>
    <geometry>
      <mesh filename="package://meshes/UR_Hand_1v3_1.stl" scale="0.001 0.001 0.001"/>
    </geometry>
    <material name="silver"/>
  </visual>
  <collision>
    <origin xyz="-0.11532232994676654 0.9925198930492037 -0.5078756084703961" rpy="0 0 0"/>
    <geometry>
      <mesh filename="package://meshes/UR_Hand_1v3_1.stl" scale="0.001 0.001 0.001"/>
    </geometry>
  </collision>
</link>

<link name="U_Neck_1v4_1">
  <inertial>
    <origin xyz="-0.00037164112238628755 -0.0021753766108381324 0.025762247824182016" rpy="0 0 0"/>
    <mass value="0.4036291829667976"/>
    <inertia ixx="0.00023" iyy="0.000129" izz="0.00023" ixy="0.0" iyz="2e-06" ixz="-1e-06"/>
  </inertial>
  <visual>
    <origin xyz="-0.07400000000095126 -2.993161274389422e-15 -0.577400499999998" rpy="0 0 0"/>
    <geometry>
      <mesh filename="package://meshes/U_Neck_1v4_1.stl" scale="0.001 0.001 0.001"/>
    </geometry>
    <material name="silver"/>
  </visual>
  <collision>
    <origin xyz="-0.07400000000095126 -2.993161274389422e-15 -0.577400499999998" rpy="0 0 0"/>
    <geometry>
      <mesh filename="package://meshes/U_Neck_1v4_1.stl" scale="0.001 0.001 0.001"/>
    </geometry>
  </collision>
</link>

<link name="LL_Hip_1v5_1">
  <inertial>
    <origin xyz="-0.06917603745290118 1.0698331936453975e-06 -0.06802640641081147" rpy="0 0 0"/>
    <mass value="2.67932667244079"/>
    <inertia ixx="0.006034" iyy="0.01107" izz="0.008699" ixy="0.0" iyz="0.0" ixz="-0.002414"/>
  </inertial>
  <visual>
    <origin xyz="-0.11000000000058899 -0.10249999999999986 0.017399500000002215" rpy="0 0 0"/>
    <geometry>
      <mesh filename="package://meshes/LL_Hip_1v5_1.stl" scale="0.001 0.001 0.001"/>
    </geometry>
    <material name="silver"/>
  </visual>
  <collision>
    <origin xyz="-0.11000000000058899 -0.10249999999999986 0.017399500000002215" rpy="0 0 0"/>
    <geometry>
      <mesh filename="package://meshes/LL_Hip_1v5_1.stl" scale="0.001 0.001 0.001"/>
    </geometry>
  </collision>
</link>

<link name="LL_Hip_2v4_1">
  <inertial>
    <origin xyz="0.04938810696726112 -0.002454451868342769 6.441730237585763e-05" rpy="0 0 0"/>
    <mass value="2.627802741394807"/>
    <inertia ixx="0.003176" iyy="0.003653" izz="0.003391" ixy="1.7e-05" iyz="-5e-06" ixz="-4e-06"/>
  </inertial>
  <visual>
    <origin xyz="-0.058000000000588775 -0.10249999999999933 0.10239950000000209" rpy="0 0 0"/>
    <geometry>
      <mesh filename="package://meshes/LL_Hip_2v4_1.stl" scale="0.001 0.001 0.001"/>
    </geometry>
    <material name="silver"/>
  </visual>
  <collision>
    <origin xyz="-0.058000000000588775 -0.10249999999999933 0.10239950000000209" rpy="0 0 0"/>
    <geometry>
      <mesh filename="package://meshes/LL_Hip_2v4_1.stl" scale="0.001 0.001 0.001"/>
    </geometry>
  </collision>
</link>

<link name="LL_Hip_3v5_1">
  <inertial>
    <origin xyz="-0.0002911220211979787 0.04472203071756335 -0.24721315449058373" rpy="0 0 0"/>
    <mass value="5.645927933397011"/>
    <inertia ixx="0.07923" iyy="0.079547" izz="0.009962" ixy="3.8e-05" iyz="-0.001546" ixz="0.00072"/>
  </inertial>
  <visual>
    <origin xyz="-0.11000000000058881 -0.0584999999999993 0.10239950000000192" rpy="0 0 0"/>
    <geometry>
      <mesh filename="package://meshes/LL_Hip_3v5_1.stl" scale="0.001 0.001 0.001"/>
    </geometry>
    <material name="silver"/>
  </visual>
  <collision>
    <origin xyz="-0.11000000000058881 -0.0584999999999993 0.10239950000000192" rpy="0 0 0"/>
    <geometry>
      <mesh filename="package://meshes/LL_Hip_3v5_1.stl" scale="0.001 0.001 0.001"/>
    </geometry>
  </collision>
</link>

<link name="LL_Ankle_1v4_1">
  <inertial>
    <origin xyz="-0.002274853408171726 0.04339540509245437 -5.944338541152838e-05" rpy="0 0 0"/>
    <mass value="2.8327636446825726"/>
    <inertia ixx="0.003548" iyy="0.004046" izz="0.00397" ixy="4e-06" iyz="5e-06" ixz="2e-06"/>
  </inertial>
  <visual>
    <origin xyz="-0.10998795286075568 -0.05850000000000075 0.8023994997926651" rpy="0 0 0"/>
    <geometry>
      <mesh filename="package://meshes/LL_Ankle_1v4_1.stl" scale="0.001 0.001 0.001"/>
    </geometry>
    <material name="silver"/>
  </visual>
  <collision>
    <origin xyz="-0.10998795286075568 -0.05850000000000075 0.8023994997926651" rpy="0 0 0"/>
    <geometry>
      <mesh filename="package://meshes/LL_Ankle_1v4_1.stl" scale="0.001 0.001 0.001"/>
    </geometry>
  </collision>
</link>

<link name="LR_Hip_3v5_1">
  <inertial>
    <origin xyz="-0.0002985760235737628 -0.04466565743110341 -0.24713640540403864" rpy="0 0 0"/>
    <mass value="5.650145116853696"/>
    <inertia ixx="0.079385" iyy="0.0797" izz="0.009967" ixy="4.1e-05" iyz="0.001537" ixz="0.000727"/>
  </inertial>
  <visual>
    <origin xyz="-0.1100000000005891 0.05850000000000075 0.10239950000000135" rpy="0 0 0"/>
    <geometry>
      <mesh filename="package://meshes/LR_Hip_3v5_1.stl" scale="0.001 0.001 0.001"/>
    </geometry>
    <material name="silver"/>
  </visual>
  <collision>
    <origin xyz="-0.1100000000005891 0.05850000000000075 0.10239950000000135" rpy="0 0 0"/>
    <geometry>
      <mesh filename="package://meshes/LR_Hip_3v5_1.stl" scale="0.001 0.001 0.001"/>
    </geometry>
  </collision>
</link>

<link name="UL_Shoulder_1v3_1">
  <inertial>
    <origin xyz="-4.8688883035413744e-05 0.004689185127778772 0.059975388405186514" rpy="0 0 0"/>
    <mass value="1.6150479626666572"/>
    <inertia ixx="0.001961" iyy="0.002031" izz="0.001713" ixy="1e-06" iyz="-8.2e-05" ixz="3e-06"/>
  </inertial>
  <visual>
    <origin xyz="-0.1330000000009497 -0.15400000000000127 -0.4254004999999977" rpy="0 0 0"/>
    <geometry>
      <mesh filename="package://meshes/UL_Shoulder_1v3_1.stl" scale="0.001 0.001 0.001"/>
    </geometry>
    <material name="silver"/>
  </visual>
  <collision>
    <origin xyz="-0.1330000000009497 -0.15400000000000127 -0.4254004999999977" rpy="0 0 0"/>
    <geometry>
      <mesh filename="package://meshes/UL_Shoulder_1v3_1.stl" scale="0.001 0.001 0.001"/>
    </geometry>
  </collision>
</link>

<link name="UR_Arm_1v2_1">
  <inertial>
    <origin xyz="-0.019856760581530353 -0.11198406637045477 -0.011879754003060405" rpy="0 0 0"/>
    <mass value="0.5866138308463256"/>
    <inertia ixx="0.003808" iyy="0.000938" izz="0.00412" ixy="-0.000374" iyz="-0.000539" ixz="-4.9e-05"/>
  </inertial>
  <visual>
    <origin xyz="-0.1330000000009493 0.43119999999999936 -0.490400500000001" rpy="0 0 0"/>
    <geometry>
      <mesh filename="package://meshes/UR_Arm_1v2_1.stl" scale="0.001 0.001 0.001"/>
    </geometry>
    <material name="silver"/>
  </visual>
  <collision>
    <origin xyz="-0.1330000000009493 0.43119999999999936 -0.490400500000001" rpy="0 0 0"/>
    <geometry>
      <mesh filename="package://meshes/UR_Arm_1v2_1.stl" scale="0.001 0.001 0.001"/>
    </geometry>
  </collision>
</link>

<link name="UR_Arm_2v6_1">
  <inertial>
    <origin xyz="-0.03048998521969251 -0.05170211148751014 0.017677742911309968" rpy="0 0 0"/>
    <mass value="1.9251420845982694"/>
    <inertia ixx="0.006136" iyy="0.001919" izz="0.005737" ixy="-6e-05" iyz="0.001465" ixz="2.2e-05"/>
  </inertial>
  <visual>
    <origin xyz="-0.1640000000009494 0.6381999999999994 -0.45790050000000143" rpy="0 0 0"/>
    <geometry>
      <mesh filename="package://meshes/UR_Arm_2v6_1.stl" scale="0.001 0.001 0.001"/>
    </geometry>
    <material name="silver"/>
  </visual>
  <collision>
    <origin xyz="-0.1640000000009494 0.6381999999999994 -0.45790050000000143" rpy="0 0 0"/>
    <geometry>
      <mesh filename="package://meshes/UR_Arm_2v6_1.stl" scale="0.001 0.001 0.001"/>
    </geometry>
  </collision>
</link>

<link name="UL_Shoulder_2v3_1">
  <inertial>
    <origin xyz="-0.0011919891845771358 0.05640482469235519 1.7398678880564677e-05" rpy="0 0 0"/>
    <mass value="0.469969679313745"/>
    <inertia ixx="0.0013" iyy="0.00077" izz="0.001461" ixy="3.8e-05" iyz="0.0" ixz="0.0"/>
  </inertial>
  <visual>
    <origin xyz="-0.13300000000095022 -0.18810000000000165 -0.4904004999999966" rpy="0 0 0"/>
    <geometry>
      <mesh filename="package://meshes/UL_Shoulder_2v3_1.stl" scale="0.001 0.001 0.001"/>
    </geometry>
    <material name="silver"/>
  </visual>
  <collision>
    <origin xyz="-0.13300000000095022 -0.18810000000000165 -0.4904004999999966" rpy="0 0 0"/>
    <geometry>
      <mesh filename="package://meshes/UL_Shoulder_2v3_1.stl" scale="0.001 0.001 0.001"/>
    </geometry>
  </collision>
</link>

<link name="UL_Shoulder_3v3_1">
  <inertial>
    <origin xyz="-0.034710314326984765 0.04860435019477388 0.000239874163706022" rpy="0 0 0"/>
    <mass value="2.8349404070306568"/>
    <inertia ixx="0.008564" iyy="0.002739" izz="0.008365" ixy="0.00034" iyz="2.6e-05" ixz="4e-06"/>
  </inertial>
  <visual>
    <origin xyz="-0.1703000000009496 -0.3031000000000019 -0.4904004999999959" rpy="0 0 0"/>
    <geometry>
      <mesh filename="package://meshes/UL_Shoulder_3v3_1.stl" scale="0.001 0.001 0.001"/>
    </geometry>
    <material name="silver"/>
  </visual>
  <collision>
    <origin xyz="-0.1703000000009496 -0.3031000000000019 -0.4904004999999959" rpy="0 0 0"/>
    <geometry>
      <mesh filename="package://meshes/UL_Shoulder_3v3_1.stl" scale="0.001 0.001 0.001"/>
    </geometry>
  </collision>
</link>

<link name="UL_Arm_1v3_1">
  <inertial>
    <origin xyz="-0.019856617512708535 0.11198346137591142 -0.01187962834379741" rpy="0 0 0"/>
    <mass value="0.5866103797070253"/>
    <inertia ixx="0.003808" iyy="0.000938" izz="0.00412" ixy="0.000374" iyz="0.000539" ixz="-4.9e-05"/>
  </inertial>
  <visual>
    <origin xyz="-0.1330000000009484 -0.431200000000002 -0.4904004999999956" rpy="0 0 0"/>
    <geometry>
      <mesh filename="package://meshes/UL_Arm_1v3_1.stl" scale="0.001 0.001 0.001"/>
    </geometry>
    <material name="silver"/>
  </visual>
  <collision>
    <origin xyz="-0.1330000000009484 -0.431200000000002 -0.4904004999999956" rpy="0 0 0"/>
    <geometry>
      <mesh filename="package://meshes/UL_Arm_1v3_1.stl" scale="0.001 0.001 0.001"/>
    </geometry>
  </collision>
</link>

<link name="UL_Arm_2v2_1">
  <inertial>
    <origin xyz="-0.03048998521968957 0.051701282625822076 0.01767774563703889" rpy="0 0 0"/>
    <mass value="1.9251420846004907"/>
    <inertia ixx="0.006136" iyy="0.00192" izz="0.005737" ixy="6e-05" iyz="-0.001465" ixz="2.2e-05"/>
  </inertial>
  <visual>
    <origin xyz="-0.16400000000094814 -0.638200000000002 -0.4579004999999944" rpy="0 0 0"/>
    <geometry>
      <mesh filename="package://meshes/UL_Arm_2v2_1.stl" scale="0.001 0.001 0.001"/>
    </geometry>
    <material name="silver"/>
  </visual>
  <collision>
    <origin xyz="-0.16400000000094814 -0.638200000000002 -0.4579004999999944" rpy="0 0 0"/>
    <geometry>
      <mesh filename="package://meshes/UL_Arm_2v2_1.stl" scale="0.001 0.001 0.001"/>
    </geometry>
  </collision>
</link>

<link name="UL_Arm_3v2_1">
  <inertial>
    <origin xyz="-0.016381147407500046 0.07699266586586007 -8.077765816516536e-06" rpy="0 0 0"/>
    <mass value="0.410266051698681"/>
    <inertia ixx="0.001446" iyy="0.000531" izz="0.001699" ixy="0.000194" iyz="-2.7e-05" ixz="3e-05"/>
  </inertial>
  <visual>
    <origin xyz="-0.1330000000009476 -0.7631999999999992 -0.4904005000000006" rpy="0 0 0"/>
    <geometry>
      <mesh filename="package://meshes/UL_Arm_3v2_1.stl" scale="0.001 0.001 0.001"/>
    </geometry>
    <material name="silver"/>
  </visual>
  <collision>
    <origin xyz="-0.1330000000009476 -0.7631999999999992 -0.4904005000000006" rpy="0 0 0"/>
    <geometry>
      <mesh filename="package://meshes/UL_Arm_3v2_1.stl" scale="0.001 0.001 0.001"/>
    </geometry>
  </collision>
</link>

<link name="UL_Wrist_1v6_1">
  <inertial>
    <origin xyz="-0.038258892983506126 0.023272677762591898 0.0047334051763253115" rpy="0 0 0"/>
    <mass value="0.7829537736721189"/>
    <inertia ixx="0.000791" iyy="0.000468" izz="0.000758" ixy="-2.3e-05" iyz="-8.8e-05" ixz="-5e-06"/>
  </inertial>
  <visual>
    <origin xyz="-0.1699999994764261 -0.9069999999999991 -0.49040049999999996" rpy="0 0 0"/>
    <geometry>
      <mesh filename="package://meshes/UL_Wrist_1v6_1.stl" scale="0.001 0.001 0.001"/>
    </geometry>
    <material name="silver"/>
  </visual>
  <collision>
    <origin xyz="-0.1699999994764261 -0.9069999999999991 -0.49040049999999996" rpy="0 0 0"/>
    <geometry>
      <mesh filename="package://meshes/UL_Wrist_1v6_1.stl" scale="0.001 0.001 0.001"/>
    </geometry>
  </collision>
</link>

<link name="UR_Wrist_1v6_1">
  <inertial>
    <origin xyz="-0.03825889298350543 -0.023264276272391693 -0.004774526607590535" rpy="0 0 0"/>
    <mass value="0.7829537736721189"/>
    <inertia ixx="0.000791" iyy="0.000469" izz="0.000758" ixy="2.3e-05" iyz="-8.9e-05" ixz="5e-06"/>
  </inertial>
  <visual>
    <origin xyz="-0.16999999947643005 0.9069998877790804 -0.4902735000495847" rpy="0 0 0"/>
    <geometry>
      <mesh filename="package://meshes/UR_Wrist_1v6_1.stl" scale="0.001 0.001 0.001"/>
    </geometry>
    <material name="silver"/>
  </visual>
  <collision>
    <origin xyz="-0.16999999947643005 0.9069998877790804 -0.4902735000495847" rpy="0 0 0"/>
    <geometry>
      <mesh filename="package://meshes/UR_Wrist_1v6_1.stl" scale="0.001 0.001 0.001"/>
    </geometry>
  </collision>
</link>

<link name="UR_Wrist_2v3_1">
  <inertial>
    <origin xyz="5.997652374745144e-11 -0.021170872308799438 -0.03160245261788569" rpy="0 0 0"/>
    <mass value="0.12362354813035466"/>
    <inertia ixx="0.000144" iyy="0.00014" izz="8.1e-05" ixy="-0.0" iyz="6e-06" ixz="0.0"/>
  </inertial>
  <visual>
    <origin xyz="-0.13299999947642896 0.9550263779182748 -0.5202310741321091" rpy="0 0 0"/>
    <geometry>
      <mesh filename="package://meshes/UR_Wrist_2v3_1.stl" scale="0.001 0.001 0.001"/>
    </geometry>
    <material name="silver"/>
  </visual>
  <collision>
    <origin xyz="-0.13299999947642896 0.9550263779182748 -0.5202310741321091" rpy="0 0 0"/>
    <geometry>
      <mesh filename="package://meshes/UR_Wrist_2v3_1.stl" scale="0.001 0.001 0.001"/>
    </geometry>
  </collision>
</link>

<link name="LR_Hip_1v2_1">
  <inertial>
    <origin xyz="-0.06917603745290099 1.0698331936315197e-06 -0.06802640641081154" rpy="0 0 0"/>
    <mass value="2.67932667244079"/>
    <inertia ixx="0.006034" iyy="0.01107" izz="0.008699" ixy="0.0" iyz="0.0" ixz="-0.002414"/>
  </inertial>
  <visual>
    <origin xyz="-0.11000000000058906 0.10250000000000024 0.017399500000001043" rpy="0 0 0"/>
    <geometry>
      <mesh filename="package://meshes/LR_Hip_1v2_1.stl" scale="0.001 0.001 0.001"/>
    </geometry>
    <material name="silver"/>
  </visual>
  <collision>
    <origin xyz="-0.11000000000058906 0.10250000000000024 0.017399500000001043" rpy="0 0 0"/>
    <geometry>
      <mesh filename="package://meshes/LR_Hip_1v2_1.stl" scale="0.001 0.001 0.001"/>
    </geometry>
  </collision>
</link>

<link name="LR_Hip_2v3_1">
  <inertial>
    <origin xyz="0.04938810696726131 0.0024544518683428523 -6.44173023760658e-05" rpy="0 0 0"/>
    <mass value="2.627802741394807"/>
    <inertia ixx="0.003176" iyy="0.003653" izz="0.003391" ixy="-1.7e-05" iyz="-5e-06" ixz="4e-06"/>
  </inertial>
  <visual>
    <origin xyz="-0.05800000000058907 0.10250000000000078 0.10239950000000089" rpy="0 0 0"/>
    <geometry>
      <mesh filename="package://meshes/LR_Hip_2v3_1.stl" scale="0.001 0.001 0.001"/>
    </geometry>
    <material name="silver"/>
  </visual>
  <collision>
    <origin xyz="-0.05800000000058907 0.10250000000000078 0.10239950000000089" rpy="0 0 0"/>
    <geometry>
      <mesh filename="package://meshes/LR_Hip_2v3_1.stl" scale="0.001 0.001 0.001"/>
    </geometry>
  </collision>
</link>

<link name="LR_Knee_1v6_1">
  <inertial>
    <origin xyz="0.00701856181762224 -0.04540804230282687 -0.16864413795205935" rpy="0 0 0"/>
    <mass value="2.613723755846661"/>
    <inertia ixx="0.028922" iyy="0.028067" izz="0.00526" ixy="-2e-06" iyz="0.000285" ixz="-0.000196"/>
  </inertial>
  <visual>
    <origin xyz="-0.10998735043189203 0.058500000000002605 0.4523994997926637" rpy="0 0 0"/>
    <geometry>
      <mesh filename="package://meshes/LR_Knee_1v6_1.stl" scale="0.001 0.001 0.001"/>
    </geometry>
    <material name="silver"/>
  </visual>
  <collision>
    <origin xyz="-0.10998735043189203 0.058500000000002605 0.4523994997926637" rpy="0 0 0"/>
    <geometry>
      <mesh filename="package://meshes/LR_Knee_1v6_1.stl" scale="0.001 0.001 0.001"/>
    </geometry>
  </collision>
</link>

<link name="LR_Ankle_1v2_1">
  <inertial>
    <origin xyz="-0.0022748534081627886 -0.04339540509245439 5.839105574845238e-05" rpy="0 0 0"/>
    <mass value="2.832763644682572"/>
    <inertia ixx="0.003548" iyy="0.004046" izz="0.00397" ixy="-4e-06" iyz="5e-06" ixz="-2e-06"/>
  </inertial>
  <visual>
    <origin xyz="-0.10998735043189249 0.05850000000000902 0.8023994997926606" rpy="0 0 0"/>
    <geometry>
      <mesh filename="package://meshes/LR_Ankle_1v2_1.stl" scale="0.001 0.001 0.001"/>
    </geometry>
    <material name="silver"/>
  </visual>
  <collision>
    <origin xyz="-0.10998735043189249 0.05850000000000902 0.8023994997926606" rpy="0 0 0"/>
    <geometry>
      <mesh filename="package://meshes/LR_Ankle_1v2_1.stl" scale="0.001 0.001 0.001"/>
    </geometry>
  </collision>
</link>

<link name="LL_Knee_1v4_1">
  <inertial>
    <origin xyz="0.00702566926825611 0.049063538692212694 -0.16846048047969997" rpy="0 0 0"/>
    <mass value="2.611079558489294"/>
    <inertia ixx="0.028908" iyy="0.027977" izz="0.005333" ixy="4.2e-05" iyz="-0.000235" ixz="-0.000193"/>
  </inertial>
  <visual>
    <origin xyz="-0.10998795286075495 -0.05849999999999432 0.4523994997926659" rpy="0 0 0"/>
    <geometry>
      <mesh filename="package://meshes/LL_Knee_1v4_1.stl" scale="0.001 0.001 0.001"/>
    </geometry>
    <material name="silver"/>
  </visual>
  <collision>
    <origin xyz="-0.10998795286075495 -0.05849999999999432 0.4523994997926659" rpy="0 0 0"/>
    <geometry>
      <mesh filename="package://meshes/LL_Knee_1v4_1.stl" scale="0.001 0.001 0.001"/>
    </geometry>
  </collision>
</link>

<link name="LL_Ankle_2v7_1">
  <inertial>
    <origin xyz="-0.01909901885143462 9.917426099839699e-05 -0.009513593537790688" rpy="0 0 0"/>
    <mass value="2.0994846031706644"/>
    <inertia ixx="0.003952" iyy="0.008647" izz="0.007228" ixy="2e-05" iyz="-5e-06" ixz="0.001901"/>
  </inertial>
  <visual>
    <origin xyz="-0.05448795286075568 -0.10250000000000069 0.8023994997926658" rpy="0 0 0"/>
    <geometry>
      <mesh filename="package://meshes/LL_Ankle_2v7_1.stl" scale="0.001 0.001 0.001"/>
    </geometry>
    <material name="silver"/>
  </visual>
  <collision>
    <origin xyz="-0.05448795286075568 -0.10250000000000069 0.8023994997926658" rpy="0 0 0"/>
    <geometry>
      <mesh filename="package://meshes/LL_Ankle_2v7_1.stl" scale="0.001 0.001 0.001"/>
    </geometry>
  </collision>
</link>

<link name="LR_Ankle_2v3_1">
  <inertial>
    <origin xyz="-0.019046716525030843 9.970492093901162e-05 -0.009558473004821155" rpy="0 0 0"/>
    <mass value="2.0896860090944918"/>
    <inertia ixx="0.003951" iyy="0.008642" izz="0.007223" ixy="2e-05" iyz="-5e-06" ixz="0.0019"/>
  </inertial>
  <visual>
    <origin xyz="-0.054487350431892595 0.1025000000000091 0.8023994997926603" rpy="0 0 0"/>
    <geometry>
      <mesh filename="package://meshes/LR_Ankle_2v3_1.stl" scale="0.001 0.001 0.001"/>
    </geometry>
    <material name="silver"/>
  </visual>
  <collision>
    <origin xyz="-0.054487350431892595 0.1025000000000091 0.8023994997926603" rpy="0 0 0"/>
    <geometry>
      <mesh filename="package://meshes/LR_Ankle_2v3_1.stl" scale="0.001 0.001 0.001"/>
    </geometry>
  </collision>
</link>

<link name="U_Neck_2_simv5_1">
  <inertial>
    <origin xyz="0.03716189401977074 -0.03828688576234904 0.07078599033712796" rpy="0 0 0"/>
    <mass value="1.4176041570545084"/>
    <inertia ixx="0.007913" iyy="0.012069" izz="0.010153" ixy="-9.4e-05" iyz="-1.9e-05" ixz="0.002562"/>
  </inertial>
  <visual>
    <origin xyz="-0.07400000000095146 -0.03750000000000324 -0.6049004999999985" rpy="0 0 0"/>
    <geometry>
      <mesh filename="package://meshes/U_Neck_2_simv5_1.stl" scale="0.001 0.001 0.001"/>
    </geometry>
    <material name="silver"/>
  </visual>
  <collision>
    <origin xyz="-0.07400000000095146 -0.03750000000000324 -0.6049004999999985" rpy="0 0 0"/>
    <geometry>
      <mesh filename="package://meshes/U_Neck_2_simv5_1.stl" scale="0.001 0.001 0.001"/>
    </geometry>
  </collision>
</link>

<link name="UL_Wrist_2v7_1">
  <inertial>
    <origin xyz="-5.24900956033747e-11 0.02122200258823359 0.03157442649869413" rpy="0 0 0"/>
    <mass value="0.11880820823347743"/>
    <inertia ixx="0.000138" iyy="0.000135" izz="7.8e-05" ixy="-0.0" iyz="5e-06" ixz="0.0"/>
  </inertial>
  <visual>
    <origin xyz="-0.13299999947642618 -0.9549734723823646 -0.46035809750654805" rpy="0 0 0"/>
    <geometry>
      <mesh filename="package://meshes/UL_Wrist_2v7_1.stl" scale="0.001 0.001 0.001"/>
    </geometry>
    <material name="silver"/>
  </visual>
  <collision>
    <origin xyz="-0.13299999947642618 -0.9549734723823646 -0.46035809750654805" rpy="0 0 0"/>
    <geometry>
      <mesh filename="package://meshes/UL_Wrist_2v7_1.stl" scale="0.001 0.001 0.001"/>
    </geometry>
  </collision>
</link>

<link name="UL_Hand_1v6_1">
  <inertial>
    <origin xyz="0.020011545651956175 0.06526504586687298 -0.04081762841853387" rpy="0 0 0"/>
    <mass value="0.3182129588272351"/>
    <inertia ixx="0.001019" iyy="0.000442" izz="0.000701" ixy="1.3e-05" iyz="0.000104" ixz="3.6e-05"/>
  </inertial>
  <visual>
    <origin xyz="-0.11532232994675917 -0.9925155871271686 -0.508002612324812" rpy="0 0 0"/>
    <geometry>
      <mesh filename="package://meshes/UL_Hand_1v6_1.stl" scale="0.001 0.001 0.001"/>
    </geometry>
    <material name="silver"/>
  </visual>
  <collision>
    <origin xyz="-0.11532232994675917 -0.9925155871271686 -0.508002612324812" rpy="0 0 0"/>
    <geometry>
      <mesh filename="package://meshes/UL_Hand_1v6_1.stl" scale="0.001 0.001 0.001"/>
    </geometry>
  </collision>
</link>

<link name="LR_Footv2_2">
  <inertial>
    <origin xyz="0.014369982409859969 8.110878067281446e-05 -0.040634094044728175" rpy="0 0 0"/>
    <mass value="2.3501326200822605"/>
    <inertia ixx="0.003415" iyy="0.012634" izz="0.014323" ixy="-1.1e-05" iyz="2e-06" ixz="0.000535"/>
  </inertial>
  <visual>
    <origin xyz="-0.1116873504318923 0.1025000000000096 0.8823994997926603" rpy="0 0 0"/>
    <geometry>
      <mesh filename="package://meshes/LR_Footv2_2.stl" scale="0.001 0.001 0.001"/>
    </geometry>
    <material name="silver"/>
  </visual>
  <collision>
    <origin xyz="-0.1116873504318923 0.1025000000000096 0.8823994997926603" rpy="0 0 0"/>
    <geometry>
      <mesh filename="package://meshes/LR_Footv2_2.stl" scale="0.001 0.001 0.001"/>
    </geometry>
  </collision>
</link>

<link name="LL_Footv1_1">
  <inertial>
    <origin xyz="0.014369982409859358 8.110878067392469e-05 -0.0406340940447284" rpy="0 0 0"/>
    <mass value="2.3501326200822605"/>
    <inertia ixx="0.003415" iyy="0.012634" izz="0.014323" ixy="-1.1e-05" iyz="2e-06" ixz="0.000535"/>
  </inertial>
  <visual>
    <origin xyz="-0.1116879528607524 -0.10250000000000041 0.8823994997926654" rpy="0 0 0"/>
    <geometry>
      <mesh filename="package://meshes/LL_Footv1_1.stl" scale="0.001 0.001 0.001"/>
    </geometry>
    <material name="silver"/>
  </visual>
  <collision>
    <origin xyz="-0.1116879528607524 -0.10250000000000041 0.8823994997926654" rpy="0 0 0"/>
    <geometry>
      <mesh filename="package://meshes/LL_Footv1_1.stl" scale="0.001 0.001 0.001"/>
    </geometry>
  </collision>
</link>

<joint name="Rev48" type="revolute">
  <origin xyz="0.11000000000058914 6.740441538255483e-16 0.11290049999999863" rpy="0 0 0"/>
  <parent link="L_Pelvisv15_1"/>
  <child link="U_Waist_2v8_1"/>
  <axis xyz="-2.363135674650191e-16 -5.813996344618051e-15 -1.0000000000000007"/>
  <limit upper="3.14159" lower="-3.14159" effort="100" velocity="100"/>
</joint>

<joint name="Rev49" type="revolute">
  <origin xyz="-2.7755575615628914e-17 0.054000000000000395 0.08499999999999971" rpy="0 0 0"/>
  <parent link="U_Waist_2v8_1"/>
  <child link="U_Waist_1v3_1"/>
  <axis xyz="1.097195604832245e-15 -1.0000000000000004 5.807057450714141e-15"/>
  <limit upper="3.14159" lower="-3.14159" effort="100" velocity="100"/>
</joint>

<joint name="Rev51" type="revolute">
  <origin xyz="-0.066 -0.053999999999999965 3.608224830031759e-16" rpy="0 0 0"/>
  <parent link="U_Waist_1v3_1"/>
  <child link="U_Body_1v21_1"/>
  <axis xyz="1.0 1.1009804560527589e-15 -7.876057159218853e-16"/>
  <limit upper="3.14159" lower="-3.14159" effort="100" velocity="100"/>
</joint>

<joint name="Rev53" type="revolute">
  <origin xyz="0.08900000000036007 -0.15400000000000022 0.2275000000000006" rpy="0 0 0"/>
  <parent link="U_Body_1v21_1"/>
  <child link="UR_Shoulder_1v3_1"/>
  <axis xyz="-5.7404775389359515e-15 -5.75101537671016e-15 -1.0000000000000002"/>
  <limit upper="3.14159" lower="-3.14159" effort="100" velocity="100"/>
</joint>

<joint name="Rev54" type="revolute">
  <origin xyz="7.771561172376096e-16 -0.03409999999999963 0.06500000000000022" rpy="0 0 0"/>
  <parent link="UR_Shoulder_1v3_1"/>
  <child link="UR_Shoulder_2v2_1"/>
  <axis xyz="-2.4980694382050493e-15 1.0000000000000002 -5.744076482806227e-15"/>
  <limit upper="3.14159" lower="-3.14159" effort="100" velocity="100"/>
</joint>

<joint name="Rev55" type="revolute">
  <origin xyz="0.03290000000000026 -0.11499999999999985 4.996003610813204e-16" rpy="0 0 0"/>
  <parent link="UR_Shoulder_2v2_1"/>
  <child link="UR_Shoulder_3v2_1"/>
  <axis xyz="1.0000000000000002 2.4703138625893572e-15 -1.0963113193475031e-14"/>
  <limit upper="3.14159" lower="-3.14159" effort="100" velocity="100"/>
</joint>

<joint name="Rev58" type="revolute">
  <origin xyz="-0.03099999999999911 -0.1250000000000001 0.03250000000000136" rpy="0 0 0"/>
  <parent link="UR_Arm_2v6_1"/>
  <child link="UR_Arm_3v3_1"/>
  <axis xyz="2.33956415450924e-15 -1.0 6.006221247925546e-15"/>
  <limit upper="3.14159" lower="-3.14159" effort="100" velocity="100"/>
</joint>

<joint name="Rigid71" type="fixed">
  <origin xyz="-0.017677669529662418 -0.03749351513092891 -0.012355465661712972" rpy="0 0 0"/>
  <parent link="UR_Wrist_2v3_1"/>
  <child link="UR_Hand_1v3_1"/>
</joint>

<joint name="Rev72" type="revolute">
  <origin xyz="0.03000000000036216 1.889913835243478e-15 0.3794999999999993" rpy="0 0 0"/>
  <parent link="U_Body_1v21_1"/>
  <child link="U_Neck_1v4_1"/>
  <axis xyz="5.742155146358386e-15 1.972284532209046e-15 1.000000000000001"/>
  <limit upper="3.14159" lower="-3.14159" effort="100" velocity="100"/>
</joint>

<joint name="Rev74" type="revolute">
  <origin xyz="0.11000000000058899 0.10249999999999986 -0.017399500000002215" rpy="0 0 0"/>
  <parent link="L_Pelvisv15_1"/>
  <child link="LL_Hip_1v5_1"/>
  <axis xyz="8.25384735534404e-16 5.7297006222583856e-15 1.0000000000000007"/>
  <limit upper="3.14159" lower="-3.14159" effort="100" velocity="100"/>
</joint>

<joint name="Rev76" type="revolute">
  <origin xyz="-0.05200000000000021 -5.273559366969494e-16 -0.08499999999999987" rpy="0 0 0"/>
  <parent link="LL_Hip_1v5_1"/>
  <child link="LL_Hip_2v4_1"/>
  <axis xyz="-1.0 -1.8369701987207869e-16 1.2858913788432647e-15"/>
  <limit upper="3.14159" lower="-3.14159" effort="100" velocity="100"/>
</joint>

<joint name="Rev77" type="revolute">
  <origin xyz="0.05200000000000003 -0.044000000000000025 1.6653345369377348e-16" rpy="0 0 0"/>
  <parent link="LL_Hip_2v4_1"/>
  <child link="LL_Hip_3v5_1"/>
  <axis xyz="-2.11452595487715e-16 1.0 -5.722761728354475e-15"/>
  <limit upper="3.14159" lower="-3.14159" effort="100" velocity="100"/>
</joint>

<joint name="Rev79" type="revolute">
  <origin xyz="7.216449660063518e-16 6.432354648922001e-15 -0.3499999999999992" rpy="0 0 0"/>
  <parent link="LL_Knee_1v4_1"/>
  <child link="LL_Ankle_1v4_1"/>
  <axis xyz="-1.586571293639183e-15 0.9999999999999984 1.4891475065716285e-14"/>
  <limit upper="3.14159" lower="-3.14159" effort="100" velocity="100"/>
</joint>

<joint name="Rev83" type="revolute">
  <origin xyz="0.052000000000000025 0.04400000000000003 -4.579669976578771e-16" rpy="0 0 0"/>
  <parent link="LR_Hip_2v3_1"/>
  <child link="LR_Hip_3v5_1"/>
  <axis xyz="2.1145259548771497e-16 -1.0 5.8452264082692096e-15"/>
  <limit upper="3.14159" lower="-3.14159" effort="100" velocity="100"/>
</joint>

<joint name="Rev87" type="revolute">
  <origin xyz="0.0890000000003606 0.15400000000000016 0.22749999999999898" rpy="0 0 0"/>
  <parent link="U_Body_1v21_1"/>
  <child link="UL_Shoulder_1v3_1"/>
  <axis xyz="-5.7404775389359515e-15 -5.671804259085645e-15 -1.0000000000000002"/>
  <limit upper="3.14159" lower="-3.14159" effort="100" velocity="100"/>
</joint>

<joint name="Rev88" type="revolute">
  <origin xyz="-0.0329000000000009 -0.12810000000000077 9.992007221626409e-16" rpy="0 0 0"/>
  <parent link="UR_Shoulder_3v2_1"/>
  <child link="UR_Arm_1v2_1"/>
  <axis xyz="-2.3395641545092494e-15 1.0000000000000067 -5.761291888096113e-15"/>
  <limit upper="3.14159" lower="-3.14159" effort="100" velocity="100"/>
</joint>

<joint name="Rev89" type="revolute">
  <origin xyz="0.031000000000000083 -0.20700000000000007 -0.032499999999999585" rpy="0 0 0"/>
  <parent link="UR_Arm_1v2_1"/>
  <child link="UR_Arm_2v6_1"/>
  <axis xyz="1.0000000000000002 2.3118085788934946e-15 -1.929460670297891e-14"/>
  <limit upper="3.14159" lower="-3.14159" effort="100" velocity="100"/>
</joint>

<joint name="Rev90" type="revolute">
  <origin xyz="5.273559366969494e-16 0.03410000000000038 0.06499999999999889" rpy="0 0 0"/>
  <parent link="UL_Shoulder_1v3_1"/>
  <child link="UL_Shoulder_2v3_1"/>
  <axis xyz="2.460537064640939e-15 -1.0000000000000016 4.917954270796613e-15"/>
  <limit upper="3.14159" lower="-3.14159" effort="100" velocity="100"/>
</joint>

<joint name="Rev91" type="revolute">
  <origin xyz="0.03729999999999939 0.11500000000000027 -6.661338147750939e-16" rpy="0 0 0"/>
  <parent link="UL_Shoulder_2v3_1"/>
  <child link="UL_Shoulder_3v3_1"/>
  <axis xyz="-1.0 -4.696389139123812e-15 8.306943523164274e-15"/>
  <limit upper="3.14159" lower="-3.14159" effort="100" velocity="100"/>
</joint>

<joint name="Rev92" type="revolute">
  <origin xyz="-0.03730000000000122 0.1281000000000001 -3.3306690738754696e-16" rpy="0 0 0"/>
  <parent link="UL_Shoulder_3v3_1"/>
  <child link="UL_Arm_1v3_1"/>
  <axis xyz="6.841802252406881e-16 -1.0000000000000064 4.919631878632668e-15"/>
  <limit upper="3.14159" lower="-3.14159" effort="100" velocity="100"/>
</joint>

<joint name="Rev93" type="revolute">
  <origin xyz="0.03099999999999975 0.20699999999999996 -0.032500000000001195" rpy="0 0 0"/>
  <parent link="UL_Arm_1v3_1"/>
  <child link="UL_Arm_2v2_1"/>
  <axis xyz="-1.0 -2.3611845461500433e-16 7.617924953484719e-15"/>
  <limit upper="3.14159" lower="-3.14159" effort="100" velocity="100"/>
</joint>

<joint name="Rev94" type="revolute">
  <origin xyz="-0.031000000000000527 0.12499999999999722 0.032500000000006246" rpy="0 0 0"/>
  <parent link="UL_Arm_2v2_1"/>
  <child link="UL_Arm_3v2_1"/>
  <axis xyz="5.573217142813753e-15 -1.0 4.917954270796584e-15"/>
  <limit upper="3.14159" lower="-3.14159" effort="100" velocity="100"/>
</joint>

<joint name="Rev96" type="revolute">
  <origin xyz="0.036999999475478496 0.14379999999999993 -6.661338147750939e-16" rpy="0 0 0"/>
  <parent link="UL_Arm_3v2_1"/>
  <child link="UL_Wrist_1v6_1"/>
  <axis xyz="0.9999999999999973 5.562263329417432e-15 3.6003605237126595e-14"/>
  <limit upper="3.14159" lower="-3.14159" effort="100" velocity="100"/>
</joint>

<joint name="Rev97" type="revolute">
  <origin xyz="0.03699999947547977 -0.14379988777908081 -0.0001269999504180941" rpy="0 0 0"/>
  <parent link="UR_Arm_3v3_1"/>
  <child link="UR_Wrist_1v6_1"/>
  <axis xyz="-0.9999999999999983 -2.2901357504330102e-15 -2.430878457392643e-14"/>
  <limit upper="3.14159" lower="-3.14159" effort="100" velocity="100"/>
</joint>

<joint name="Rev99" type="revolute">
  <origin xyz="-0.03700000000000109 -0.048026490139194467 0.02995757408252442" rpy="0 0 0"/>
  <parent link="UR_Wrist_1v6_1"/>
  <child link="UR_Wrist_2v3_1"/>
  <axis xyz="2.1181817340233713e-14 0.0008836292804559096 -0.9999996095995707"/>
  <limit upper="3.14159" lower="-3.14159" effort="100" velocity="100"/>
</joint>

<joint name="Rev100" type="revolute">
  <origin xyz="0.11000000000058906 -0.10250000000000024 -0.017399500000001043" rpy="0 0 0"/>
  <parent link="L_Pelvisv15_1"/>
  <child link="LR_Hip_1v2_1"/>
  <axis xyz="-3.812955256843554e-16 5.7297006222583856e-15 1.0000000000000007"/>
  <limit upper="3.14159" lower="-3.14159" effort="100" velocity="100"/>
</joint>

<joint name="Rev101" type="revolute">
  <origin xyz="-0.051999999999999984 -5.412337245047638e-16 -0.08499999999999985" rpy="0 0 0"/>
  <parent link="LR_Hip_1v2_1"/>
  <child link="LR_Hip_2v3_1"/>
  <axis xyz="-1.0 -1.836970198720939e-16 -1.2858913788432734e-15"/>
  <limit upper="3.14159" lower="-3.14159" effort="100" velocity="100"/>
</joint>

<joint name="Rev102" type="revolute">
  <origin xyz="-1.2649568697065128e-05 -1.85268467234323e-15 -0.34999999979266233" rpy="0 0 0"/>
  <parent link="LR_Hip_3v5_1"/>
  <child link="LR_Knee_1v6_1"/>
  <axis xyz="2.726849354450827e-16 -1.0 5.655912434966384e-15"/>
  <limit upper="3.14159" lower="-3.14159" effort="100" velocity="100"/>
</joint>

<joint name="Rev103" type="revolute">
  <origin xyz="4.579669976578771e-16 -6.411537967210279e-15 -0.34999999999999687" rpy="0 0 0"/>
  <parent link="LR_Knee_1v6_1"/>
  <child link="LR_Ankle_1v2_1"/>
  <axis xyz="1.1589312317372247e-16 0.9999999999999962 -6.5849780853703926e-15"/>
  <limit upper="3.14159" lower="-3.14159" effort="100" velocity="100"/>
</joint>

<joint name="Rev104" type="revolute">
  <origin xyz="-1.204713983385397e-05 -4.98212582300539e-15 -0.349999999792664" rpy="0 0 0"/>
  <parent link="LL_Hip_3v5_1"/>
  <child link="LL_Knee_1v4_1"/>
  <axis xyz="-1.5865712936391844e-15 0.9999999999999998 1.4891475065716307e-14"/>
  <limit upper="3.14159" lower="-3.14159" effort="100" velocity="100"/>
</joint>

<joint name="Rev105" type="revolute">
  <origin xyz="-0.055499999999999994 0.043999999999999935 -6.661338147750939e-16" rpy="0 0 0"/>
  <parent link="LL_Ankle_1v4_1"/>
  <child link="LL_Ankle_2v7_1"/>
  <axis xyz="-1.0 -1.558815718023532e-15 -2.489306744864395e-15"/>
  <limit upper="3.14159" lower="-3.14159" effort="100" velocity="100"/>
</joint>

<joint name="Rev106" type="revolute">
  <origin xyz="-0.0554999999999999 -0.04400000000000008 2.220446049250313e-16" rpy="0 0 0"/>
  <parent link="LR_Ankle_1v2_1"/>
  <child link="LR_Ankle_2v3_1"/>
  <axis xyz="-1.0 1.4364869878934398e-16 -1.1973296993332904e-15"/>
  <limit upper="3.14159" lower="-3.14159" effort="100" velocity="100"/>
</joint>

<joint name="Rev107" type="revolute">
  <origin xyz="1.942890293094024e-16 0.03750000000000025 0.027500000000000524" rpy="0 0 0"/>
  <parent link="U_Neck_1v4_1"/>
  <child link="U_Neck_2_simv5_1"/>
  <axis xyz="1.0864392049532897e-15 -1.0000000000000013 5.390367565838198e-15"/>
  <limit upper="3.14159" lower="-3.14159" effort="100" velocity="100"/>
</joint>

<joint name="Rev108" type="revolute">
  <origin xyz="-0.03699999999999992 0.04797347238236549 -0.030042402493451914" rpy="0 0 0"/>
  <parent link="UL_Wrist_1v6_1"/>
  <child link="UL_Wrist_2v7_1"/>
  <axis xyz="-3.764595716628752e-14 0.0008836292804672098 0.9999996095995708"/>
  <limit upper="3.14159" lower="-3.14159" effort="100" velocity="100"/>
</joint>

<joint name="Rigid109" type="fixed">
  <origin xyz="-0.01767766952966701 0.037542114744803956 0.04764451481826398" rpy="0 0 0"/>
  <parent link="UL_Wrist_2v7_1"/>
  <child link="UL_Hand_1v6_1"/>
</joint>

<joint name="Rigid111" type="fixed">
  <origin xyz="0.05719999999999971 -4.996003610813204e-16 -0.07999999999999996" rpy="0 0 0"/>
  <parent link="LR_Ankle_2v3_1"/>
  <child link="LR_Footv2_2"/>
</joint>

<joint name="Rigid113" type="fixed">
  <origin xyz="0.057199999999996726 -2.7755575615628914e-16 -0.07999999999999963" rpy="0 0 0"/>
  <parent link="LL_Ankle_2v7_1"/>
  <child link="LL_Footv1_1"/>
</joint>

</robot>
